Workbook

Sheet IPL_2020_to_2025_Raw
A1: season | B1: player_name | C1: team | D1: team_abbr | E1: role | F1: matches | G1: innings | H1: runs | I1: HS | J1: bat_avg | K1: SR | L1: 4s | M1: 6s | N1: 50s | O1: 100s | P1: not_outs | Q1: wickets | R1: overs | S1: economy | T1: bowl_avg | U1: bowl_SR | V1: best_bowling | W1: catches | X1: nationality | Y1: Indian/Overseas | Z1: Highest Run Scorer | AA1: Highest Wicket Taker
A2: 2020 | B2: KL Rahul | C2: Kings XI Punjab | D2: KXIP | E2: WK-Batsman | F2: 14 | G2: 14 | H2: 670 | I2: 132* | J2: 55.83 | K2: 129.34 | L2: 66 | M2: 23 | N2: 5 | O2: 1 | P2: 2 | Q2: 0 | R2: 0 | S2: 0 | T2: 0 | U2: 0 | V2: 0/0 | W2: 7 | X2: Indian | Y2: =IF(X2="Indian","Indian","Overseas") -> Indian
A3: 2020 | B3: Shikhar Dhawan | C3: Delhi Capitals | D3: DC | E3: Batsman | F3: 16 | G3: 16 | H3: 618 | I3: 106* | J3: 44.14 | K3: 145.07 | L3: 68 | M3: 15 | N3: 8 | O3: 2 | P3: 2 | Q3: 0 | R3: 0 | S3: 0 | T3: 0 | U3: 0 | V3: 0/0 | W3: 10 | X3: Indian | Y3: =IF(X3="Indian","Indian","Overseas") -> Indian
A4: 2020 | B4: David Warner | C4: Sunrisers Hyderabad | D4: SRH | E4: Batsman | F4: 16 | G4: 16 | H4: 548 | I4: 85 | J4: 34.25 | K4: 134.97 | L4: 55 | M4: 21 | N4: 4 | O4: 0 | P4: 0 | Q4: 0 | R4: 0 | S4: 0 | T4: 0 | U4: 0 | V4: 0/0 | W4: 11 | X4: Australian | Y4: =IF(X4="Indian","Indian","Overseas") -> Overseas
A5: 2020 | B5: Quinton de Kock | C5: Mumbai Indians | D5: MI | E5: WK-Batsman | F5: 16 | G5: 16 | H5: 503 | I5: 78 | J5: 33.53 | K5: 140.5 | L5: 54 | M5: 18 | N5: 3 | O5: 0 | P5: 1 | Q5: 0 | R5: 0 | S5: 0 | T5: 0 | U5: 0 | V5: 0/0 | W5: 9 | X5: South African | Y5: =IF(X5="Indian","Indian","Overseas") -> Overseas
A6: 2020 | B6: Ishan Kishan | C6: Mumbai Indians | D6: MI | E6: WK-Batsman | F6: 14 | G6: 14 | H6: 516 | I6: 99 | J6: 43 | K6: 145.76 | L6: 44 | M6: 28 | N6: 3 | O6: 0 | P6: 2 | Q6: 0 | R6: 0 | S6: 0 | T6: 0 | U6: 0 | V6: 0/0 | W6: 7 | X6: Indian | Y6: =IF(X6="Indian","Indian","Overseas") -> Indian
A7: 2020 | B7: AB de Villiers | C7: Royal Challengers Bengaluru | D7: RCB | E7: WK-Batsman | F7: 15 | G7: 13 | H7: 454 | I7: 73 | J7: 56.75 | K7: 158.74 | L7: 33 | M7: 34 | N7: 4 | O7: 0 | P7: 6 | Q7: 0 | R7: 0 | S7: 0 | T7: 0 | U7: 0 | V7: 0/0 | W7: 9 | X7: South African | Y7: =IF(X7="Indian","Indian","Overseas") -> Overseas
A8: 2020 | B8: Mayank Agarwal | C8: Kings XI Punjab | D8: KXIP | E8: Batsman | F8: 14 | G8: 14 | H8: 424 | I8: 106 | J8: 34.28 | K8: 158.8 | L8: 38 | M8: 26 | N8: 3 | O8: 1 | P8: 0 | Q8: 0 | R8: 0 | S8: 0 | T8: 0 | U8: 0 | V8: 0/0 | W8: 6 | X8: Indian | Y8: =IF(X8="Indian","Indian","Overseas") -> Indian
A9: 2020 | B9: Faf du Plessis | C9: Chennai Super Kings | D9: CSK | E9: Batsman | F9: 13 | G9: 13 | H9: 449 | I9: 87* | J9: 41 | K9: 140.94 | L9: 40 | M9: 16 | N9: 5 | O9: 0 | P9: 3 | Q9: 0 | R9: 0 | S9: 0 | T9: 0 | U9: 0 | V9: 0/0 | W9: 8 | X9: South African | Y9: =IF(X9="Indian","Indian","Overseas") -> Overseas
A10: 2020 | B10: Rohit Sharma | C10: Mumbai Indians | D10: MI | E10: Batsman | F10: 12 | G10: 11 | H10: 332 | I10: 80 | J10: 36.89 | K10: 137.19 | L10: 31 | M10: 12 | N10: 2 | O10: 0 | P10: 1 | Q10: 0 | R10: 0 | S10: 0 | T10: 0 | U10: 0 | V10: 0/0 | W10: 5 | X10: Indian | Y10: =IF(X10="Indian","Indian","Overseas") -> Indian
A11: 2020 | B11: Sanju Samson | C11: Rajasthan Royals | D11: RR | E11: WK-Batsman | F11: 14 | G11: 14 | H11: 375 | I11: 85 | J11: 28.84 | K11: 147.64 | L11: 36 | M11: 18 | N11: 3 | O11: 0 | P11: 1 | Q11: 0 | R11: 0 | S11: 0 | T11: 0 | U11: 0 | V11: 0/0 | W11: 8 | X11: Indian | Y11: =IF(X11="Indian","Indian","Overseas") -> Indian
A12: 2020 | B12: Devdutt Padikkal | C12: Royal Challengers Bengaluru | D12: RCB | E12: Batsman | F12: 15 | G12: 15 | H12: 473 | I12: 74 | J12: 31.53 | K12: 124.8 | L12: 48 | M12: 12 | N12: 3 | O12: 0 | P12: 0 | Q12: 0 | R12: 0 | S12: 0 | T12: 0 | U12: 0 | V12: 0/0 | W12: 9 | X12: Indian | Y12: =IF(X12="Indian","Indian","Overseas") -> Indian
A13: 2020 | B13: Hardik Pandya | C13: Mumbai Indians | D13: MI | E13: All-Rounder | F13: 15 | G13: 11 | H13: 281 | I13: 60* | J13: 35.12 | K13: 178.34 | L13: 20 | M13: 22 | N13: 1 | O13: 0 | P13: 5 | Q13: 17 | R13: 38 | S13: 9.12 | T13: 28.47 | U13: 19.41 | V13: 3/14 | W13: 7 | X13: Indian | Y13: =IF(X13="Indian","Indian","Overseas") -> Indian
A14: 2020 | B14: Kieron Pollard | C14: Mumbai Indians | D14: MI | E14: All-Rounder | F14: 16 | G14: 14 | H14: 268 | I14: 60* | J14: 29.78 | K14: 191.43 | L14: 13 | M14: 28 | N14: 0 | O14: 0 | P14: 8 | Q14: 0 | R14: 4 | S14: 8.75 | T14: 0 | U14: 0 | V14: 0/0 | W14: 7 | X14: West Indian | Y14: =IF(X14="Indian","Indian","Overseas") -> Overseas
A15: 2020 | B15: Jasprit Bumrah | C15: Mumbai Indians | D15: MI | E15: Bowler | F15: 15 | G15: 2 | H15: 4 | I15: 3 | J15: 2 | K15: 80 | L15: 0 | M15: 0 | N15: 0 | O15: 0 | P15: 0 | Q15: 27 | R15: 58.1 | S15: 6.73 | T15: 14.59 | U15: 12.93 | V15: 4/14 | W15: 5 | X15: Indian | Y15: =IF(X15="Indian","Indian","Overseas") -> Indian
A16: 2020 | B16: Kagiso Rabada | C16: Delhi Capitals | D16: DC | E16: Bowler | F16: 17 | G16: 3 | H16: 18 | I16: 11 | J16: 9 | K16: 100 | L16: 2 | M16: 0 | N16: 0 | O16: 0 | P16: 0 | Q16: 30 | R16: 64 | S16: 8.34 | T16: 16.73 | U16: 12.8 | V16: 4/24 | W16: 3 | X16: South African | Y16: =IF(X16="Indian","Indian","Overseas") -> Overseas
A17: 2020 | B17: Trent Boult | C17: Mumbai Indians | D17: MI | E17: Bowler | F17: 15 | G17: 1 | H17: 3 | I17: 3 | J17: 3 | K17: 75 | L17: 0 | M17: 0 | N17: 0 | O17: 0 | P17: 0 | Q17: 25 | R17: 57.3 | S17: 7.97 | T17: 18.16 | U17: 13.8 | V17: 3/21 | W17: 3 | X17: New Zealand | Y17: =IF(X17="Indian","Indian","Overseas") -> Overseas
A18: 2020 | B18: Anrich Nortje | C18: Delhi Capitals | D18: DC | E18: Bowler | F18: 16 | G18: 1 | H18: 3 | I18: 3 | J18: 3 | K18: 75 | L18: 0 | M18: 0 | N18: 0 | O18: 0 | P18: 0 | Q18: 22 | R18: 58 | S18: 8.37 | T18: 19.54 | U18: 15.81 | V18: 3/21 | W18: 2 | X18: South African | Y18: =IF(X18="Indian","Indian","Overseas") -> Overseas
A19: 2020 | B19: Yuzvendra Chahal | C19: Royal Challengers Bengaluru | D19: RCB | E19: Bowler | F19: 15 | G19: 1 | H19: 2 | I19: 2 | J19: 2 | K19: 66.67 | L19: 0 | M19: 0 | N19: 0 | O19: 0 | P19: 0 | Q19: 21 | R19: 58 | S19: 8.02 | T19: 22.09 | U19: 16.57 | V19: 3/18 | W19: 9 | X19: Indian | Y19: =IF(X19="Indian","Indian","Overseas") -> Indian
A20: 2020 | B20: Rashid Khan | C20: Sunrisers Hyderabad | D20: SRH | E20: Bowler | F20: 16 | G20: 4 | H20: 22 | I20: 18 | J20: 5.5 | K20: 115.79 | L20: 2 | M20: 0 | N20: 0 | O20: 0 | P20: 0 | Q20: 20 | R20: 60 | S20: 5.37 | T20: 16.1 | U20: 18 | V20: 2/14 | W20: 12 | X20: Afghan | Y20: =IF(X20="Indian","Indian","Overseas") -> Overseas
A21: 2020 | B21: Mohammed Shami | C21: Kings XI Punjab | D21: KXIP | E21: Bowler | F21: 14 | G21: 1 | H21: 4 | I21: 4 | J21: 4 | K21: 80 | L21: 0 | M21: 0 | N21: 0 | O21: 0 | P21: 0 | Q21: 20 | R21: 54 | S21: 8.56 | T21: 23.15 | U21: 16.2 | V21: 3/15 | W21: 2 | X21: Indian | Y21: =IF(X21="Indian","Indian","Overseas") -> Indian
A22: 2020 | B22: Axar Patel | C22: Delhi Capitals | D22: DC | E22: All-Rounder | F22: 16 | G22: 8 | H22: 100 | I22: 42 | J22: 14.29 | K22: 114.94 | L22: 8 | M22: 2 | N22: 0 | O22: 0 | P22: 3 | Q22: 14 | R22: 54.5 | S22: 6.41 | T22: 22.21 | U22: 23.5 | V22: 3/22 | W22: 8 | X22: Indian | Y22: =IF(X22="Indian","Indian","Overseas") -> Indian
A23: 2020 | B23: Suresh Raina | C23: Chennai Super Kings | D23: CSK | E23: Batsman | F23: 0 | G23: 0 | H23: N/A | I23: N/A | J23: N/A | K23: N/A | L23: N/A | M23: N/A | N23: N/A | O23: N/A | P23: N/A | Q23: 0 | R23: 0 | S23: 0 | T23: 0 | U23: 0 | V23: 0/0 | W23: 0 | X23: Indian | Y23: =IF(X23="Indian","Indian","Overseas") -> Indian
A24: 2020 | B24: Ben Stokes | C24: Rajasthan Royals | D24: RR | E24: All-Rounder | F24: 14 | G24: 14 | H24: 285 | I24: 107* | J24: 23.75 | K24: 128.83 | L24: 24 | M24: 12 | N24: 0 | O24: 1 | P24: 0 | Q24: 8 | R24: 36 | S24: 8.22 | T24: 35 | U24: 27 | V24: 2/20 | W24: 7 | X24: English | Y24: =IF(X24="Indian","Indian","Overseas") -> Overseas
A25: 2021 | B25: Ruturaj Gaikwad | C25: Chennai Super Kings | D25: CSK | E25: Batsman | F25: 16 | G25: 16 | H25: 635 | I25: 101* | J25: 45.35 | K25: 136.26 | L25: 60 | M25: 22 | N25: 4 | O25: 1 | P25: 3 | Q25: 0 | R25: 0 | S25: 0 | T25: 0 | U25: 0 | V25: 0/0 | W25: 8 | X25: Indian | Y25: =IF(X25="Indian","Indian","Overseas") -> Indian
A26: 2021 | B26: Faf du Plessis | C26: Chennai Super Kings | D26: CSK | E26: Batsman | F26: 16 | G26: 16 | H26: 633 | I26: 86 | J26: 44.5 | K26: 133.19 | L26: 64 | M26: 22 | N26: 6 | O26: 0 | P26: 2 | Q26: 0 | R26: 0 | S26: 0 | T26: 0 | U26: 0 | V26: 0/0 | W26: 10 | X26: South African | Y26: =IF(X26="Indian","Indian","Overseas") -> Overseas
A27: 2021 | B27: KL Rahul | C27: Punjab Kings | D27: PBKS | E27: WK-Batsman | F27: 13 | G27: 13 | H27: 626 | I27: 91 | J27: 52.17 | K27: 136.75 | L27: 48 | M27: 22 | N27: 6 | O27: 0 | P27: 3 | Q27: 0 | R27: 0 | S27: 0 | T27: 0 | U27: 0 | V27: 0/0 | W27: 9 | X27: Indian | Y27: =IF(X27="Indian","Indian","Overseas") -> Indian
A28: 2021 | B28: Shikhar Dhawan | C28: Delhi Capitals | D28: DC | E28: Batsman | F28: 16 | G28: 16 | H28: 587 | I28: 92 | J28: 46.15 | K28: 122.37 | L28: 68 | M28: 10 | N28: 7 | O28: 0 | P28: 3 | Q28: 0 | R28: 0 | S28: 0 | T28: 0 | U28: 0 | V28: 0/0 | W28: 11 | X28: Indian | Y28: =IF(X28="Indian","Indian","Overseas") -> Indian
A29: 2021 | B29: Glenn Maxwell | C29: Royal Challengers Bengaluru | D29: RCB | E29: All-Rounder | F29: 15 | G29: 15 | H29: 513 | I29: 78 | J29: 36.64 | K29: 144.38 | L29: 36 | M29: 30 | N29: 5 | O29: 0 | P29: 1 | Q29: 3 | R29: 12 | S29: 8.08 | T29: 32.33 | U29: 24 | V29: 1/14 | W29: 8 | X29: Australian | Y29: =IF(X29="Indian","Indian","Overseas") -> Overseas
A30: 2021 | B30: Suryakumar Yadav | C30: Mumbai Indians | D30: MI | E30: Batsman | F30: 14 | G30: 14 | H30: 479 | I30: 82 | J30: 41.65 | K30: 162.71 | L30: 42 | M30: 26 | N30: 4 | O30: 0 | P30: 3 | Q30: 0 | R30: 0 | S30: 0 | T30: 0 | U30: 0 | V30: 0/0 | W30: 7 | X30: Indian | Y30: =IF(X30="Indian","Indian","Overseas") -> Indian
A31: 2021 | B31: Rituraj Gaikwad | C31: Chennai Super Kings | D31: CSK | E31: Batsman | F31: 1 | G31: 1 | H31: 12 | I31: 12 | J31: 12 | K31: 100 | L31: 1 | M31: 0 | N31: 0 | O31: 0 | P31: 0 | Q31: 0 | R31: 0 | S31: 0 | T31: 0 | U31: 0 | V31: 0/0 | W31: 0 | X31: Indian | Y31: =IF(X31="Indian","Indian","Overseas") -> Indian
A32: 2021 | B32: Sanju Samson | C32: Rajasthan Royals | D32: RR | E32: WK-Batsman | F32: 14 | G32: 14 | H32: 484 | I32: 119 | J32: 37.23 | K32: 145.63 | L32: 42 | M32: 22 | N32: 3 | O32: 1 | P32: 1 | Q32: 0 | R32: 0 | S32: 0 | T32: 0 | U32: 0 | V32: 0/0 | W32: 10 | X32: Indian | Y32: =IF(X32="Indian","Indian","Overseas") -> Indian
A33: 2021 | B33: David Warner | C33: Sunrisers Hyderabad | D33: SRH | E33: Batsman | F33: 8 | G33: 8 | H33: 195 | I33: 57 | J33: 27.86 | K33: 104.28 | L33: 20 | M33: 6 | N33: 1 | O33: 0 | P33: 1 | Q33: 0 | R33: 0 | S33: 0 | T33: 0 | U33: 0 | V33: 0/0 | W33: 4 | X33: Australian | Y33: =IF(X33="Indian","Indian","Overseas") -> Overseas
A34: 2021 | B34: Virat Kohli | C34: Royal Challengers Bengaluru | D34: RCB | E34: Batsman | F34: 15 | G34: 15 | H34: 405 | I34: 72 | J34: 29.3 | K34: 119.12 | L34: 40 | M34: 8 | N34: 3 | O34: 0 | P34: 2 | Q34: 0 | R34: 0 | S34: 0 | T34: 0 | U34: 0 | V34: 0/0 | W34: 11 | X34: Indian | Y34: =IF(X34="Indian","Indian","Overseas") -> Indian
A35: 2021 | B35: Harshal Patel | C35: Royal Challengers Bengaluru | D35: RCB | E35: Bowler | F35: 15 | G35: 4 | H35: 54 | I35: 23 | J35: 13.5 | K35: 124.41 | L35: 3 | M35: 3 | N35: 0 | O35: 0 | P35: 0 | Q35: 32 | R35: 57 | S35: 8.14 | T35: 14.34 | U35: 10.68 | V35: 5/27 | W35: 5 | X35: Indian | Y35: =IF(X35="Indian","Indian","Overseas") -> Indian
A36: 2021 | B36: Avesh Khan | C36: Delhi Capitals | D36: DC | E36: Bowler | F36: 16 | G36: 1 | H36: 3 | I36: 3 | J36: 3 | K36: 75 | L36: 0 | M36: 0 | N36: 0 | O36: 0 | P36: 0 | Q36: 24 | R36: 58 | S36: 7.37 | T36: 18.16 | U36: 14.5 | V36: 4/24 | W36: 2 | X36: Indian | Y36: =IF(X36="Indian","Indian","Overseas") -> Indian
A37: 2021 | B37: Jasprit Bumrah | C37: Mumbai Indians | D37: MI | E37: Bowler | F37: 15 | G37: 1 | H37: 5 | I37: 5 | J37: 5 | K37: 100 | L37: 0 | M37: 0 | N37: 0 | O37: 0 | P37: 0 | Q37: 21 | R37: 57.4 | S37: 7.42 | T37: 20.09 | U37: 16.47 | V37: 4/18 | W37: 3 | X37: Indian | Y37: =IF(X37="Indian","Indian","Overseas") -> Indian
... A43: 2021 | B43: Sunil Narine | C43: Kolkata Knight Riders | D43: KKR | E43: All-Rounder | F43: 16 | G43: 11 | H43: 164 | I43: 47 | J43: 18.22 | K43: 163.16 | L43: 12 | M43: 14 | N43: 0 | O43: 0 | P43: 2 | Q43: 21 | R43: 60 | S43: 6.22 | T43: 17.28 | U43: 17.14 | V43: 4/21 | W43: 10 | X43: West Indian | Y43: =IF(X43="Indian","Indian","Overseas") -> Overseas
A44: 2021 | B44: MS Dhoni | C44: Chennai Super Kings | D44: CSK | E44: WK-Batsman | F44: 16 | G44: 7 | H44: 114 | I44: 18* | J44: 38 | K44: 131.03 | L44: 6 | M44: 8 | N44: 0 | O44: 0 | P44: 7 | Q44: 0 | R44: 0 | S44: 0 | T44: 0 | U44: 0 | V44: 0/0 | W44: 9 | X44: Indian | Y44: =IF(X44="Indian","Indian","Overseas") -> Indian
A45: 2021 | B45: Devdutt Padikkal | C45: Royal Challengers Bengaluru | D45: RCB | E45: Batsman | F45: 14 | G45: 14 | H45: 392 | I45: 101 | J45: 30.15 | K45: 129.37 | L45: 40 | M45: 10 | N45: 1 | O45: 1 | P45: 1 | Q45: 0 | R45: 0 | S45: 0 | T45: 0 | U45: 0 | V45: 0/0 | W45: 6 | X45: Indian | Y45: =IF(X45="Indian","Indian","Overseas") -> Indian
...

Sheet ORANGE_CAP_HISTORY
A1: 🟠 ORANGE CAP WINNERS & 5 TOP SCORERS 2020–2025
A2: Season | B2: Rank | C2: Player | D2: Team | E2: Runs | F2: Innings | G2: Average | H2: SR | I2: 100s | J2: 50s
A3: 2020 | B3: 1 | C3: {=XLOOKUP(E3, IPL_2020_to_2025_Raw!H:H, IPL_2020_to_2025_Raw!B:B)} -> KL Rahul | D3: {=XLOOKUP(E3, IPL_2020_to_2025_Raw!H:H, IPL_2020_to_2025_Raw!D:D)} -> KXIP | E3: =IFERROR(__xludf.DUMMYFUNCTION("LARGE(FILTER(IPL_2020_to_2025_Raw!H:H, IPL_2020_to_2025_Raw!A:A=A3), VALUE(B3))"),670.0) -> 670 | F3: {=XLOOKUP(E3,IPL_2020_to_2025_Raw!H:H,IPL_2020_to_2025_Raw!G:G)} -> 14 | G3: {=XLOOKUP(E3,IPL_2020_to_2025_Raw!H:H,IPL_2020_to_2025_Raw!J:J)} -> 55.83 | H3: {=XLOOKUP(E3,IPL_2020_to_2025_Raw!H:H,IPL_2020_to_2025_Raw!K:K)} -> 129.34 | I3: {=XLOOKUP(E3,IPL_2020_to_2025_Raw!H:H,IPL_2020_to_2025_Raw!O:O)} -> 1 | J3: {=XLOOKUP(E3,IPL_2020_to_2025_Raw!H:H,IPL_2020_to_2025_Raw!N:N)} -> 5
A4: 2020 | B4: 2 | C4: {=XLOOKUP(E4, IPL_2020_to_2025_Raw!H:H, IPL_2020_to_2025_Raw!B:B)} -> Shikhar Dhawan | D4: {=XLOOKUP(E4, IPL_2020_to_2025_Raw!H:H, IPL_2020_to_2025_Raw!D:D)} -> DC | E4: =IFERROR(__xludf.DUMMYFUNCTION("LARGE(FILTER(IPL_2020_to_2025_Raw!H:H, IPL_2020_to_2025_Raw!A:A=A4), VALUE(B4))"),618.0) -> 618 | F4: {=XLOOKUP(E4,IPL_2020_to_2025_Raw!H:H,IPL_2020_to_2025_Raw!G:G)} -> 16 | G4: {=XLOOKUP(E4,IPL_2020_to_2025_Raw!H:H,IPL_2020_to_2025_Raw!J:J)} -> 44.14 | H4: {=XLOOKUP(E4,IPL_2020_to_2025_Raw!H:H,IPL_2020_to_2025_Raw!K:K)} -> 145.07 | I4: {=XLOOKUP(E4,IPL_2020_to_2025_Raw!H:H,IPL_2020_to_2025_Raw!O:O)} -> 2 | J4: {=XLOOKUP(E4,IPL_2020_to_2025_Raw!H:H,IPL_2020_to_2025_Raw!N:N)} -> 8
A5: 2020 | B5: 3 | C5: {=XLOOKUP(E5, IPL_2020_to_2025_Raw!H:H, IPL_2020_to_2025_Raw!B:B)} -> David Warner | D5: {=XLOOKUP(E5, IPL_2020_to_2025_Raw!H:H, IPL_2020_to_2025_Raw!D:D)} -> SRH | E5: =IFERROR(__xludf.DUMMYFUNCTION("LARGE(FILTER(IPL_2020_to_2025_Raw!H:H, IPL_2020_to_2025_Raw!A:A=A5), VALUE(B5))"),548.0) -> 548 | F5: {=XLOOKUP(E5,IPL_2020_to_2025_Raw!H:H,IPL_2020_to_2025_Raw!G:G)} -> 16 | G5: {=XLOOKUP(E5,IPL_2020_to_2025_Raw!H:H,IPL_2020_to_2025_Raw!J:J)} -> 34.25 | H5: {=XLOOKUP(E5,IPL_2020_to_2025_Raw!H:H,IPL_2020_to_2025_Raw!K:K)} -> 134.97 | I5: {=XLOOKUP(E5,IPL_2020_to_2025_Raw!H:H,IPL_2020_to_2025_Raw!O:O)} -> 0 | J5: {=XLOOKUP(E5,IPL_2020_to_2025_Raw!H:H,IPL_2020_to_2025_Raw!N:N)} -> 4
A6: 2020 | B6: 4 | C6: {=XLOOKUP(E6, IPL_2020_to_2025_Raw!H:H, IPL_2020_to_2025_Raw!B:B)} -> Ishan Kishan | D6: {=XLOOKUP(E6, IPL_2020_to_2025_Raw!H:H, IPL_2020_to_2025_Raw!D:D)} -> MI | E6: =IFERROR(__xludf.DUMMYFUNCTION("LARGE(FILTER(IPL_2020_to_2025_Raw!H:H, IPL_2020_to_2025_Raw!A:A=A6), VALUE(B6))"),516.0) -> 516 | F6: {=XLOOKUP(E6,IPL_2020_to_2025_Raw!H:H,IPL_2020_to_2025_Raw!G:G)} -> 14 | G6: {=XLOOKUP(E6,IPL_2020_to_2025_Raw!H:H,IPL_2020_to_2025_Raw!J:J)} -> 43 | H6: {=XLOOKUP(E6,IPL_2020_to_2025_Raw!H:H,IPL_2020_to_2025_Raw!K:K)} -> 145.76 | I6: {=XLOOKUP(E6,IPL_2020_to_2025_Raw!H:H,IPL_2020_to_2025_Raw!O:O)} -> 0 | J6: {=XLOOKUP(E6,IPL_2020_to_2025_Raw!H:H,IPL_2020_to_2025_Raw!N:N)} -> 3
A7: 2020 | B7: 5 | C7: {=XLOOKUP(E7, IPL_2020_to_2025_Raw!H:H, IPL_2020_to_2025_Raw!B:B)} -> Quinton de Kock | D7: {=XLOOKUP(E7, IPL_2020_to_2025_Raw!H:H, IPL_2020_to_2025_Raw!D:D)} -> MI | E7: =IFERROR(__xludf.DUMMYFUNCTION("LARGE(FILTER(IPL_2020_to_2025_Raw!H:H, IPL_2020_to_2025_Raw!A:A=A7), VALUE(B7))"),503.0) -> 503 | F7: {=XLOOKUP(E7,IPL_2020_to_2025_Raw!H:H,IPL_2020_to_2025_Raw!G:G)} -> 16 | G7: {=XLOOKUP(E7,IPL_2020_to_2025_Raw!H:H,IPL_2020_to_2025_Raw!J:J)} -> 33.53 | H7: {=XLOOKUP(E7,IPL_2020_to_2025_Raw!H:H,IPL_2020_to_2025_Raw!K:K)} -> 140.5 | I7: {=XLOOKUP(E7,IPL_2020_to_2025_Raw!H:H,IPL_2020_to_2025_Raw!O:O)} -> 0 | J7: {=XLOOKUP(E7,IPL_2020_to_2025_Raw!H:H,IPL_2020_to_2025_Raw!N:N)} -> 3
A8: 2021 | B8: 1 | C8: {=XLOOKUP(E8, IPL_2020_to_2025_Raw!H:H, IPL_2020_to_2025_Raw!B:B)} -> Ruturaj Gaikwad | D8: {=XLOOKUP(E8, IPL_2020_to_2025_Raw!H:H, IPL_2020_to_2025_Raw!D:D)} -> CSK | E8: =IFERROR(__xludf.DUMMYFUNCTION("LARGE(FILTER(IPL_2020_to_2025_Raw!H:H, IPL_2020_to_2025_Raw!A:A=A8), VALUE(B8))"),635.0) -> 635 | F8: {=XLOOKUP(E8,IPL_2020_to_2025_Raw!H:H,IPL_2020_to_2025_Raw!G:G)} -> 16 | G8: {=XLOOKUP(E8,IPL_2020_to_2025_Raw!H:H,IPL_2020_to_2025_Raw!J:J)} -> 45.35 | H8: {=XLOOKUP(E8,IPL_2020_to_2025_Raw!H:H,IPL_2020_to_2025_Raw!K:K)} -> 136.26 | I8: {=XLOOKUP(E8,IPL_2020_to_2025_Raw!H:H,IPL_2020_to_2025_Raw!O:O)} -> 1 | J8: {=XLOOKUP(E8,IPL_2020_to_2025_Raw!H:H,IPL_2020_to_2025_Raw!N:N)} -> 4
A9: 2021 | B9: 2 | C9: {=XLOOKUP(E9, IPL_2020_to_2025_Raw!H:H, IPL_2020_to_2025_Raw!B:B)} -> Faf du Plessis | D9: {=XLOOKUP(E9, IPL_2020_to_2025_Raw!H:H, IPL_2020_to_2025_Raw!D:D)} -> CSK | E9: =IFERROR(__xludf.DUMMYFUNCTION("LARGE(FILTER(IPL_2020_to_2025_Raw!H:H, IPL_2020_to_2025_Raw!A:A=A9), VALUE(B9))"),633.0) -> 633 | F9: {=XLOOKUP(E9,IPL_2020_to_2025_Raw!H:H,IPL_2020_to_2025_Raw!G:G)} -> 16 | G9: {=XLOOKUP(E9,IPL_2020_to_2025_Raw!H:H,IPL_2020_to_2025_Raw!J:J)} -> 44.5 | H9: {=XLOOKUP(E9,IPL_2020_to_2025_Raw!H:H,IPL_2020_to_2025_Raw!K:K)} -> 133.19 | I9: {=XLOOKUP(E9,IPL_2020_to_2025_Raw!H:H,IPL_2020_to_2025_Raw!O:O)} -> 0 | J9: {=XLOOKUP(E9,IPL_2020_to_2025_Raw!H:H,IPL_2020_to_2025_Raw!N:N)} -> 6
A10: 2021 | B10: 3 | C10: {=XLOOKUP(E10, IPL_2020_to_2025_Raw!H:H, IPL_2020_to_2025_Raw!B:B)} -> KL Rahul | D10: {=XLOOKUP(E10, IPL_2020_to_2025_Raw!H:H, IPL_2020_to_2025_Raw!D:D)} -> PBKS | E10: =IFERROR(__xludf.DUMMYFUNCTION("LARGE(FILTER(IPL_2020_to_2025_Raw!H:H, IPL_2020_to_2025_Raw!A:A=A10), VALUE(B10))"),626.0) -> 626 | F10: {=XLOOKUP(E10,IPL_2020_to_2025_Raw!H:H,IPL_2020_to_2025_Raw!G:G)} -> 13 | G10: {=XLOOKUP(E10,IPL_2020_to_2025_Raw!H:H,IPL_2020_to_2025_Raw!J:J)} -> 52.17 | H10: {=XLOOKUP(E10,IPL_2020_to_2025_Raw!H:H,IPL_2020_to_2025_Raw!K:K)} -> 136.75 | I10: {=XLOOKUP(E10,IPL_2020_to_2025_Raw!H:H,IPL_2020_to_2025_Raw!O:O)} -> 0 | J10: {=XLOOKUP(E10,IPL_2020_to_2025_Raw!H:H,IPL_2020_to_2025_Raw!N:N)} -> 6
A11: 2021 | B11: 4 | C11: {=XLOOKUP(E11, IPL_2020_to_2025_Raw!H:H, IPL_2020_to_2025_Raw!B:B)} -> Shikhar Dhawan | D11: {=XLOOKUP(E11, IPL_2020_to_2025_Raw!H:H, IPL_2020_to_2025_Raw!D:D)} -> DC | E11: =IFERROR(__xludf.DUMMYFUNCTION("LARGE(FILTER(IPL_2020_to_2025_Raw!H:H, IPL_2020_to_2025_Raw!A:A=A11), VALUE(B11))"),587.0) -> 587 | F11: {=XLOOKUP(E11,IPL_2020_to_2025_Raw!H:H,IPL_2020_to_2025_Raw!G:G)} -> 16 | G11: {=XLOOKUP(E11,IPL_2020_to_2025_Raw!H:H,IPL_2020_to_2025_Raw!J:J)} -> 46.15 | H11: {=XLOOKUP(E11,IPL_2020_to_2025_Raw!H:H,IPL_2020_to_2025_Raw!K:K)} -> 122.37 | I11: {=XLOOKUP(E11,IPL_2020_to_2025_Raw!H:H,IPL_2020_to_2025_Raw!O:O)} -> 0 | J11: {=XLOOKUP(E11,IPL_2020_to_2025_Raw!H:H,IPL_2020_to_2025_Raw!N:N)} -> 7
A12: 2021 | B12: 5 | C12: {=XLOOKUP(E12, IPL_2020_to_2025_Raw!H:H, IPL_2020_to_2025_Raw!B:B)} -> Glenn Maxwell | D12: {=XLOOKUP(E12, IPL_2020_to_2025_Raw!H:H, IPL_2020_to_2025_Raw!D:D)} -> RCB | E12: =IFERROR(__xludf.DUMMYFUNCTION("LARGE(FILTER(IPL_2020_to_2025_Raw!H:H, IPL_2020_to_2025_Raw!A:A=A12), VALUE(B12))"),513.0) -> 513 | F12: {=XLOOKUP(E12,IPL_2020_to_2025_Raw!H:H,IPL_2020_to_2025_Raw!G:G)} -> 15 | G12: {=XLOOKUP(E12,IPL_2020_to_2025_Raw!H:H,IPL_2020_to_2025_Raw!J:J)} -> 36.64 | H12: {=XLOOKUP(E12,IPL_2020_to_2025_Raw!H:H,IPL_2020_to_2025_Raw!K:K)} -> 144.38 | I12: {=XLOOKUP(E12,IPL_2020_to_2025_Raw!H:H,IPL_2020_to_2025_Raw!O:O)} -> 0 | J12: {=XLOOKUP(E12,IPL_2020_to_2025_Raw!H:H,IPL_2020_to_2025_Raw!N:N)} -> 5
A13: 2022 | B13: 1 | C13: {=XLOOKUP(E13, IPL_2020_to_2025_Raw!H:H, IPL_2020_to_2025_Raw!B:B)} -> Jos Buttler | D13: {=XLOOKUP(E13, IPL_2020_to_2025_Raw!H:H, IPL_2020_to_2025_Raw!D:D)} -> RR | E13: =IFERROR(__xludf.DUMMYFUNCTION("LARGE(FILTER(IPL_2020_to_2025_Raw!H:H, IPL_2020_to_2025_Raw!A:A=A13), VALUE(B13))"),863.0) -> 863 | F13: {=XLOOKUP(E13,IPL_2020_to_2025_Raw!H:H,IPL_2020_to_2025_Raw!G:G)} -> 17 | G13: {=XLOOKUP(E13,IPL_2020_to_2025_Raw!H:H,IPL_2020_to_2025_Raw!J:J)} -> 57.53 | H13: {=XLOOKUP(E13,IPL_2020_to_2025_Raw!H:H,IPL_2020_to_2025_Raw!K:K)} -> 149.05 | I13: {=XLOOKUP(E13,IPL_2020_to_2025_Raw!H:H,IPL_2020_to_2025_Raw!O:O)} -> 4 | J13: {=XLOOKUP(E13,IPL_2020_to_2025_Raw!H:H,IPL_2020_to_2025_Raw!N:N)} -> 4
A14: 2022 | B14: 2 | C14: {=XLOOKUP(E14, IPL_2020_to_2025_Raw!H:H, IPL_2020_to_2025_Raw!B:B)} -> KL Rahul | D14: {=XLOOKUP(E14, IPL_2020_to_2025_Raw!H:H, IPL_2020_to_2025_Raw!D:D)} -> LSG | E14: =IFERROR(__xludf.DUMMYFUNCTION("LARGE(FILTER(IPL_2020_to_2025_Raw!H:H, IPL_2020_to_2025_Raw!A:A=A14), VALUE(B14))"),616.0) -> 616 | F14: {=XLOOKUP(E14,IPL_2020_to_2025_Raw!H:H,IPL_2020_to_2025_Raw!G:G)} -> 15 | G14: {=XLOOKUP(E14,IPL_2020_to_2025_Raw!H:H,IPL_2020_to_2025_Raw!J:J)} -> 51.33 | H14: {=XLOOKUP(E14,IPL_2020_to_2025_Raw!H:H,IPL_2020_to_2025_Raw!K:K)} -> 135.68 | I14: {=XLOOKUP(E14,IPL_2020_to_2025_Raw!H:H,IPL_2020_to_2025_Raw!O:O)} -> 2 | J14: {=XLOOKUP(E14,IPL_2020_to_2025_Raw!H:H,IPL_2020_to_2025_Raw!N:N)} -> 4
A15: 2022 | B15: 3 | C15: {=XLOOKUP(E15, IPL_2020_to_2025_Raw!H:H, IPL_2020_to_2025_Raw!B:B)} -> Quinton de Kock | D15: {=XLOOKUP(E15, IPL_2020_to_2025_Raw!H:H, IPL_2020_to_2025_Raw!D:D)} -> LSG | E15: =IFERROR(__xludf.DUMMYFUNCTION("LARGE(FILTER(IPL_2020_to_2025_Raw!H:H, IPL_2020_to_2025_Raw!A:A=A15), VALUE(B15))"),508.0) -> 508 | F15: {=XLOOKUP(E15,IPL_2020_to_2025_Raw!H:H,IPL_2020_to_2025_Raw!G:G)} -> 16 | G15: {=XLOOKUP(E15,IPL_2020_to_2025_Raw!H:H,IPL_2020_to_2025_Raw!J:J)} -> 33.87 | H15: {=XLOOKUP(E15,IPL_2020_to_2025_Raw!H:H,IPL_2020_to_2025_Raw!K:K)} -> 153.77 | I15: {=XLOOKUP(E15,IPL_2020_to_2025_Raw!H:H,IPL_2020_to_2025_Raw!O:O)} -> 1 | J15: {=XLOOKUP(E15,IPL_2020_to_2025_Raw!H:H,IPL_2020_to_2025_Raw!N:N)} -> 3
A16: 2022 | B16: 4 | C16: {=XLOOKUP(E16, IPL_2020_to_2025_Raw!H:H, IPL_2020_to_2025_Raw!B:B)} -> Hardik Pandya | D16: {=XLOOKUP(E16, IPL_2020_to_2025_Raw!H:H, IPL_2020_to_2025_Raw!D:D)} -> GT | E16: =IFERROR(__xludf.DUMMYFUNCTION("LARGE(FILTER(IPL_2020_to_2025_Raw!H:H, IPL_2020_to_2025_Raw!A:A=A16), VALUE(B16))"),487.0) -> 487 | F16: {=XLOOKUP(E16,IPL_2020_to_2025_Raw!H:H,IPL_2020_to_2025_Raw!G:G)} -> 13 | G16: {=XLOOKUP(E16,IPL_2020_to_2025_Raw!H:H,IPL_2020_to_2025_Raw!J:J)} -> 44.27 | H16: {=XLOOKUP(E16,IPL_2020_to_2025_Raw!H:H,IPL_2020_to_2025_Raw!K:K)} -> 131.27 | I16: {=XLOOKUP(E16,IPL_2020_to_2025_Raw!H:H,IPL_2020_to_2025_Raw!O:O)} -> 0 | J16: {=XLOOKUP(E16,IPL_2020_to_2025_Raw!H:H,IPL_2020_to_2025_Raw!N:N)} -> 3
A17: 2022 | B17: 5 | C17: {=XLOOKUP(E17, IPL_2020_to_2025_Raw!H:H, IPL_2020_to_2025_Raw!B:B)} -> Shubman Gill | D17: {=XLOOKUP(E17, IPL_2020_to_2025_Raw!H:H, IPL_2020_to_2025_Raw!D:D)} -> GT | E17: =IFERROR(__xludf.DUMMYFUNCTION("LARGE(FILTER(IPL_2020_to_2025_Raw!H:H, IPL_2020_to_2025_Raw!A:A=A17), VALUE(B17))"),483.0) -> 483 | F17: {=XLOOKUP(E17,IPL_2020_to_2025_Raw!H:H,IPL_2020_to_2025_Raw!G:G)} -> 16 | G17: {=XLOOKUP(E17,IPL_2020_to_2025_Raw!H:H,IPL_2020_to_2025_Raw!J:J)} -> 35.07 | H17: {=XLOOKUP(E17,IPL_2020_to_2025_Raw!H:H,IPL_2020_to_2025_Raw!K:K)} -> 133.97 | I17: {=XLOOKUP(E17,IPL_2020_to_2025_Raw!H:H,IPL_2020_to_2025_Raw!O:O)} -> 0 | J17: {=XLOOKUP(E17,IPL_2020_to_2025_Raw!H:H,IPL_2020_to_2025_Raw!N:N)} -> 4
A18: 2023 | B18: 1 | C18: {=XLOOKUP(E18, IPL_2020_to_2025_Raw!H:H, IPL_2020_to_2025_Raw!B:B)} -> Shubman Gill | D18: {=XLOOKUP(E18, IPL_2020_to_2025_Raw!H:H, IPL_2020_to_2025_Raw!D:D)} -> GT | E18: =IFERROR(__xludf.DUMMYFUNCTION("LARGE(FILTER(IPL_2020_to_2025_Raw!H:H, IPL_2020_to_2025_Raw!A:A=A18), VALUE(B18))"),890.0) -> 890 | F18: {=XLOOKUP(E18,IPL_2020_to_2025_Raw!H:H,IPL_2020_to_2025_Raw!G:G)} -> 17 | G18: {=XLOOKUP(E18,IPL_2020_to_2025_Raw!H:H,IPL_2020_to_2025_Raw!J:J)} -> 59.33 | H18: {=XLOOKUP(E18,IPL_2020_to_2025_Raw!H:H,IPL_2020_to_2025_Raw!K:K)} -> 157.7 | I18: {=XLOOKUP(E18,IPL_2020_to_2025_Raw!H:H,IPL_2020_to_2025_Raw!O:O)} -> 3 | J18: {=XLOOKUP(E18,IPL_2020_to_2025_Raw!H:H,IPL_2020_to_2025_Raw!N:N)} -> 4
A19: 2023 | B19: 2 | C19: {=XLOOKUP(E19, IPL_2020_to_2025_Raw!H:H, IPL_2020_to_2025_Raw!B:B)} -> Faf du Plessis | D19: {=XLOOKUP(E19, IPL_2020_to_2025_Raw!H:H, IPL_2020_to_2025_Raw!D:D)} -> RCB | E19: =IFERROR(__xludf.DUMMYFUNCTION("LARGE(FILTER(IPL_2020_to_2025_Raw!H:H, IPL_2020_to_2025_Raw!A:A=A19), VALUE(B19))"),730.0) -> 730 | F19: {=XLOOKUP(E19,IPL_2020_to_2025_Raw!H:H,IPL_2020_to_2025_Raw!G:G)} -> 14 | G19: {=XLOOKUP(E19,IPL_2020_to_2025_Raw!H:H,IPL_2020_to_2025_Raw!J:J)} -> 58.4 | H19: {=XLOOKUP(E19,IPL_2020_to_2025_Raw!H:H,IPL_2020_to_2025_Raw!K:K)} -> 157.24 | I19: {=XLOOKUP(E19,IPL_2020_to_2025_Raw!H:H,IPL_2020_to_2025_Raw!O:O)} -> 0 | J19: {=XLOOKUP(E19,IPL_2020_to_2025_Raw!H:H,IPL_2020_to_2025_Raw!N:N)} -> 7
A20: 2023 | B20: 3 | C20: {=XLOOKUP(E20, IPL_2020_to_2025_Raw!H:H, IPL_2020_to_2025_Raw!B:B)} -> Devon Conway | D20: {=XLOOKUP(E20, IPL_2020_to_2025_Raw!H:H, IPL_2020_to_2025_Raw!D:D)} -> CSK | E20: =IFERROR(__xludf.DUMMYFUNCTION("LARGE(FILTER(IPL_2020_to_2025_Raw!H:H, IPL_2020_to_2025_Raw!A:A=A20), VALUE(B20))"),672.0) -> 672 | F20: {=XLOOKUP(E20,IPL_2020_to_2025_Raw!H:H,IPL_2020_to_2025_Raw!G:G)} -> 16 | G20: {=XLOOKUP(E20,IPL_2020_to_2025_Raw!H:H,IPL_2020_to_2025_Raw!J:J)} -> 48 | H20: {=XLOOKUP(E20,IPL_2020_to_2025_Raw!H:H,IPL_2020_to_2025_Raw!K:K)} -> 138.55 | I20: {=XLOOKUP(E20,IPL_2020_to_2025_Raw!H:H,IPL_2020_to_2025_Raw!O:O)} -> 0 | J20: {=XLOOKUP(E20,IPL_2020_to_2025_Raw!H:H,IPL_2020_to_2025_Raw!N:N)} -> 6
A21: 2023 | B21: 4 | C21: {=XLOOKUP(E21, IPL_2020_to_2025_Raw!H:H, IPL_2020_to_2025_Raw!B:B)} -> Virat Kohli | D21: {=XLOOKUP(E21, IPL_2020_to_2025_Raw!H:H, IPL_2020_to_2025_Raw!D:D)} -> RCB | E21: =IFERROR(__xludf.DUMMYFUNCTION("LARGE(FILTER(IPL_2020_to_2025_Raw!H:H, IPL_2020_to_2025_Raw!A:A=A21), VALUE(B21))"),639.0) -> 639 | F21: {=XLOOKUP(E21,IPL_2020_to_2025_Raw!H:H,IPL_2020_to_2025_Raw!G:G)} -> 14 | G21: {=XLOOKUP(E21,IPL_2020_to_2025_Raw!H:H,IPL_2020_to_2025_Raw!J:J)} -> 48.03 | H21: {=XLOOKUP(E21,IPL_2020_to_2025_Raw!H:H,IPL_2020_to_2025_Raw!K:K)} -> 139.78 | I21: {=XLOOKUP(E21,IPL_2020_to_2025_Raw!H:H,IPL_2020_to_2025_Raw!O:O)} -> 1 | J21: {=XLOOKUP(E21,IPL_2020_to_2025_Raw!H:H,IPL_2020_to_2025_Raw!N:N)} -> 6
A22: 2023 | B22: 5 | C22: {=XLOOKUP(E22, IPL_2020_to_2025_Raw!H:H, IPL_2020_to_2025_Raw!B:B)} -> Yashasvi Jaiswal | D22: {=XLOOKUP(E22, IPL_2020_to_2025_Raw!H:H, IPL_2020_to_2025_Raw!D:D)} -> RR | E22: =IFERROR(__xludf.DUMMYFUNCTION("LARGE(FILTER(IPL_2020_to_2025_Raw!H:H, IPL_2020_to_2025_Raw!A:A=A22), VALUE(B22))"),625.0) -> 625 | F22: {=XLOOKUP(E22,IPL_2020_to_2025_Raw!H:H,IPL_2020_to_2025_Raw!G:G)} -> 14 | G22: {=XLOOKUP(E22,IPL_2020_to_2025_Raw!H:H,IPL_2020_to_2025_Raw!J:J)} -> 47.07 | H22: {=XLOOKUP(E22,IPL_2020_to_2025_Raw!H:H,IPL_2020_to_2025_Raw!K:K)} -> 163.61 | I22: {=XLOOKUP(E22,IPL_2020_to_2025_Raw!H:H,IPL_2020_to_2025_Raw!O:O)} -> 1 | J22: {=XLOOKUP(E22,IPL_2020_to_2025_Raw!H:H,IPL_2020_to_2025_Raw!N:N)} -> 5
A23: 2024 | B23: 1 | C23: {=XLOOKUP(E23, IPL_2020_to_2025_Raw!H:H, IPL_2020_to_2025_Raw!B:B)} -> Virat Kohli | D23: {=XLOOKUP(E23, IPL_2020_to_2025_Raw!H:H, IPL_2020_to_2025_Raw!D:D)} -> RCB | E23: =IFERROR(__xludf.DUMMYFUNCTION("LARGE(FILTER(IPL_2020_to_2025_Raw!H:H, IPL_2020_to_2025_Raw!A:A=A23), VALUE(B23))"),741.0) -> 741 | F23: {=XLOOKUP(E23,IPL_2020_to_2025_Raw!H:H,IPL_2020_to_2025_Raw!G:G)} -> 15 | G23: {=XLOOKUP(E23,IPL_2020_to_2025_Raw!H:H,IPL_2020_to_2025_Raw!J:J)} -> 61.75 | H23: {=XLOOKUP(E23,IPL_2020_to_2025_Raw!H:H,IPL_2020_to_2025_Raw!K:K)} -> 154.69 | I23: {=XLOOKUP(E23,IPL_2020_to_2025_Raw!H:H,IPL_2020_to_2025_Raw!O:O)} -> 1 | J23: {=XLOOKUP(E23,IPL_2020_to_2025_Raw!H:H,IPL_2020_to_2025_Raw!N:N)} -> 6
A24: 2024 | B24: 2 | C24: {=XLOOKUP(E24, IPL_2020_to_2025_Raw!H:H, IPL_2020_to_2025_Raw!B:B)} -> Ruturaj Gaikwad | D24: {=XLOOKUP(E24, IPL_2020_to_2025_Raw!H:H, IPL_2020_to_2025_Raw!D:D)} -> CSK | E24: =IFERROR(__xludf.DUMMYFUNCTION("LARGE(FILTER(IPL_2020_to_2025_Raw!H:H, IPL_2020_to_2025_Raw!A:A=A24), VALUE(B24))"),583.0) -> 583 | F24: {=XLOOKUP(E24,IPL_2020_to_2025_Raw!H:H,IPL_2020_to_2025_Raw!G:G)} -> 15 | G24: {=XLOOKUP(E24,IPL_2020_to_2025_Raw!H:H,IPL_2020_to_2025_Raw!J:J)} -> 43.55 | H24: {=XLOOKUP(E24,IPL_2020_to_2025_Raw!H:H,IPL_2020_to_2025_Raw!K:K)} -> 141.11 | I24: {=XLOOKUP(E24,IPL_2020_to_2025_Raw!H:H,IPL_2020_to_2025_Raw!O:O)} -> 0 | J24: {=XLOOKUP(E24,IPL_2020_to_2025_Raw!H:H,IPL_2020_to_2025_Raw!N:N)} -> 5
A25: 2024 | B25: 3 | C25: {=XLOOKUP(E25, IPL_2020_to_2025_Raw!H:H, IPL_2020_to_2025_Raw!B:B)} -> Riyan Parag | D25: {=XLOOKUP(E25, IPL_2020_to_2025_Raw!H:H, IPL_2020_to_2025_Raw!D:D)} -> RR | E25: =IFERROR(__xludf.DUMMYFUNCTION("LARGE(FILTER(IPL_2020_to_2025_Raw!H:H, IPL_2020_to_2025_Raw!A:A=A25), VALUE(B25))"),573.0) -> 573 | F25: {=XLOOKUP(E25,IPL_2020_to_2025_Raw!H:H,IPL_2020_to_2025_Raw!G:G)} -> 14 | G25: {=XLOOKUP(E25,IPL_2020_to_2025_Raw!H:H,IPL_2020_to_2025_Raw!J:J)} -> 47.75 | H25: {=XLOOKUP(E25,IPL_2020_to_2025_Raw!H:H,IPL_2020_to_2025_Raw!K:K)} -> 149.6 | I25: {=XLOOKUP(E25,IPL_2020_to_2025_Raw!H:H,IPL_2020_to_2025_Raw!O:O)} -> 0 | J25: {=XLOOKUP(E25,IPL_2020_to_2025_Raw!H:H,IPL_2020_to_2025_Raw!N:N)} -> 5
A26: 2024 | B26: 4 | C26: {=XLOOKUP(E26, IPL_2020_to_2025_Raw!H:H, IPL_2020_to_2025_Raw!B:B)} -> Travis Head | D26: {=XLOOKUP(E26, IPL_2020_to_2025_Raw!H:H, IPL_2020_to_2025_Raw!D:D)} -> SRH | E26: =IFERROR(__xludf.DUMMYFUNCTION("LARGE(FILTER(IPL_2020_to_2025_Raw!H:H, IPL_2020_to_2025_Raw!A:A=A26), VALUE(B26))"),567.0) -> 567 | F26: {=XLOOKUP(E26,IPL_2020_to_2025_Raw!H:H,IPL_2020_to_2025_Raw!G:G)} -> 15 | G26: {=XLOOKUP(E26,IPL_2020_to_2025_Raw!H:H,IPL_2020_to_2025_Raw!J:J)} -> 42 | H26: {=XLOOKUP(E26,IPL_2020_to_2025_Raw!H:H,IPL_2020_to_2025_Raw!K:K)} -> 191.55 | I26: {=XLOOKUP(E26,IPL_2020_to_2025_Raw!H:H,IPL_2020_to_2025_Raw!O:O)} -> 1 | J26: {=XLOOKUP(E26,IPL_2020_to_2025_Raw!H:H,IPL_2020_to_2025_Raw!N:N)} -> 2
A27: 2024 | B27: 5 | C27: {=XLOOKUP(E27, IPL_2020_to_2025_Raw!H:H, IPL_2020_to_2025_Raw!B:B)} -> Sanju Samson | D27: {=XLOOKUP(E27, IPL_2020_to_2025_Raw!H:H, IPL_2020_to_2025_Raw!D:D)} -> RR | E27: =IFERROR(__xludf.DUMMYFUNCTION("LARGE(FILTER(IPL_2020_to_2025_Raw!H:H, IPL_2020_to_2025_Raw!A:A=A27), VALUE(B27))"),531.0) -> 531 | F27: {=XLOOKUP(E27,IPL_2020_to_2025_Raw!H:H,IPL_2020_to_2025_Raw!G:G)} -> 12 | G27: {=XLOOKUP(E27,IPL_2020_to_2025_Raw!H:H,IPL_2020_to_2025_Raw!J:J)} -> 53.1 | H27: {=XLOOKUP(E27,IPL_2020_to_2025_Raw!H:H,IPL_2020_to_2025_Raw!K:K)} -> 160.6 | I27: {=XLOOKUP(E27,IPL_2020_to_2025_Raw!H:H,IPL_2020_to_2025_Raw!O:O)} -> 0 | J27: {=XLOOKUP(E27,IPL_2020_to_2025_Raw!H:H,IPL_2020_to_2025_Raw!N:N)} -> 4
A28: 2025 | B28: 1 | C28: {=XLOOKUP(E28, IPL_2020_to_2025_Raw!H:H, IPL_2020_to_2025_Raw!B:B)} -> Sai Sudharsan | D28: {=XLOOKUP(E28, IPL_2020_to_2025_Raw!H:H, IPL_2020_to_2025_Raw!D:D)} -> GT | E28: =IFERROR(__xludf.DUMMYFUNCTION("LARGE(FILTER(IPL_2020_to_2025_Raw!H:H, IPL_2020_to_2025_Raw!A:A=A28), VALUE(B28))"),759.0) -> 759 | F28: {=XLOOKUP(E28,IPL_2020_to_2025_Raw!H:H,IPL_2020_to_2025_Raw!G:G)} -> 16 | G28: {=XLOOKUP(E28,IPL_2020_to_2025_Raw!H:H,IPL_2020_to_2025_Raw!J:J)} -> 54.21 | H28: {=XLOOKUP(E28,IPL_2020_to_2025_Raw!H:H,IPL_2020_to_2025_Raw!K:K)} -> 156.91 | I28: {=XLOOKUP(E28,IPL_2020_to_2025_Raw!H:H,IPL_2020_to_2025_Raw!O:O)} -> 1 | J28: {=XLOOKUP(E28,IPL_2020_to_2025_Raw!H:H,IPL_2020_to_2025_Raw!N:N)} -> 6
A29: 2025 | B29: 2 | C29: {=XLOOKUP(E29, IPL_2020_to_2025_Raw!H:H, IPL_2020_to_2025_Raw!B:B)} -> Virat Kohli | D29: {=XLOOKUP(E29, IPL_2020_to_2025_Raw!H:H, IPL_2020_to_2025_Raw!D:D)} -> RCB | E29: =IFERROR(__xludf.DUMMYFUNCTION("LARGE(FILTER(IPL_2020_to_2025_Raw!H:H, IPL_2020_to_2025_Raw!A:A=A29), VALUE(B29))"),741.0) -> 741 | F29: {=XLOOKUP(E29,IPL_2020_to_2025_Raw!H:H,IPL_2020_to_2025_Raw!G:G)} -> 15 | G29: {=XLOOKUP(E29,IPL_2020_to_2025_Raw!H:H,IPL_2020_to_2025_Raw!J:J)} -> 61.75 | H29: {=XLOOKUP(E29,IPL_2020_to_2025_Raw!H:H,IPL_2020_to_2025_Raw!K:K)} -> 154.69 | I29: {=XLOOKUP(E29,IPL_2020_to_2025_Raw!H:H,IPL_2020_to_2025_Raw!O:O)} -> 1 | J29: {=XLOOKUP(E29,IPL_2020_to_2025_Raw!H:H,IPL_2020_to_2025_Raw!N:N)} -> 6
A30: 2025 | B30: 3 | C30: {=XLOOKUP(E30, IPL_2020_to_2025_Raw!H:H, IPL_2020_to_2025_Raw!B:B)} -> Shubman Gill | D30: {=XLOOKUP(E30, IPL_2020_to_2025_Raw!H:H, IPL_2020_to_2025_Raw!D:D)} -> GT | E30: =IFERROR(__xludf.DUMMYFUNCTION("LARGE(FILTER(IPL_2020_to_2025_Raw!H:H, IPL_2020_to_2025_Raw!A:A=A30), VALUE(B30))"),649.0) -> 649 | F30: {=XLOOKUP(E30,IPL_2020_to_2025_Raw!H:H,IPL_2020_to_2025_Raw!G:G)} -> 14 | G30: {=XLOOKUP(E30,IPL_2020_to_2025_Raw!H:H,IPL_2020_to_2025_Raw!J:J)} -> 54.08 | H30: {=XLOOKUP(E30,IPL_2020_to_2025_Raw!H:H,IPL_2020_to_2025_Raw!K:K)} -> 156.38 | I30: {=XLOOKUP(E30,IPL_2020_to_2025_Raw!H:H,IPL_2020_to_2025_Raw!O:O)} -> 0 | J30: {=XLOOKUP(E30,IPL_2020_to_2025_Raw!H:H,IPL_2020_to_2025_Raw!N:N)} -> 6
A31: 2025 | B31: 4 | C31: {=XLOOKUP(E31, IPL_2020_to_2025_Raw!H:H, IPL_2020_to_2025_Raw!B:B)} -> Suryakumar Yadav | D31: {=XLOOKUP(E31, IPL_2020_to_2025_Raw!H:H, IPL_2020_to_2025_Raw!D:D)} -> MI | E31: =IFERROR(__xludf.DUMMYFUNCTION("LARGE(FILTER(IPL_2020_to_2025_Raw!H:H, IPL_2020_to_2025_Raw!A:A=A31), VALUE(B31))"),640.0) -> 640 | F31: {=XLOOKUP(E31,IPL_2020_to_2025_Raw!H:H,IPL_2020_to_2025_Raw!G:G)} -> 14 | G31: {=XLOOKUP(E31,IPL_2020_to_2025_Raw!H:H,IPL_2020_to_2025_Raw!J:J)} -> 71.11 | H31: {=XLOOKUP(E31,IPL_2020_to_2025_Raw!H:H,IPL_2020_to_2025_Raw!K:K)} -> 167.97 | I31: {=XLOOKUP(E31,IPL_2020_to_2025_Raw!H:H,IPL_2020_to_2025_Raw!O:O)} -> 0 | J31: {=XLOOKUP(E31,IPL_2020_to_2025_Raw!H:H,IPL_2020_to_2025_Raw!N:N)} -> 5
A32: 2025 | B32: 5 | C32: {=XLOOKUP(E32, IPL_2020_to_2025_Raw!H:H, IPL_2020_to_2025_Raw!B:B)} -> Mitchell Marsh | D32: {=XLOOKUP(E32, IPL_2020_to_2025_Raw!H:H, IPL_2020_to_2025_Raw!D:D)} -> LSG | E32: =IFERROR(__xludf.DUMMYFUNCTION("LARGE(FILTER(IPL_2020_to_2025_Raw!H:H, IPL_2020_to_2025_Raw!A:A=A32), VALUE(B32))"),627.0) -> 627 | F32: {=XLOOKUP(E32,IPL_2020_to_2025_Raw!H:H,IPL_2020_to_2025_Raw!G:G)} -> 13 | G32: {=XLOOKUP(E32,IPL_2020_to_2025_Raw!H:H,IPL_2020_to_2025_Raw!J:J)} -> 48.23 | H32: {=XLOOKUP(E32,IPL_2020_to_2025_Raw!H:H,IPL_2020_to_2025_Raw!K:K)} -> 163.7 | I32: {=XLOOKUP(E32,IPL_2020_to_2025_Raw!H:H,IPL_2020_to_2025_Raw!O:O)} -> 1 | J32: {=XLOOKUP(E32,IPL_2020_to_2025_Raw!H:H,IPL_2020_to_2025_Raw!N:N)} -> 6

Sheet PURPLE_CAP_HISTORY
A1: 🟣 PURPLE CAP WINNERS & 5 TOP WICKET-TAKERS 2020–2025
A2: Season | B2: Rank | C2: Player | D2: Team | E2: Wickets | F2: Overs | G2: Economy | H2: Best
A3: 2020 | B3: 1 | C3: =IFERROR(__xludf.DUMMYFUNCTION("INDEX( SORT( FILTER({IPL_2020_to_2025_Raw!B:B, IPL_2020_to_2025_Raw!C:C,IPL_2020_to_2025_Raw!Q:Q}, IPL_2020_to_2025_Raw!A:A=A3), 3,FALSE), B3,1)"),"Kagiso Rabada") -> Kagiso Rabada | D3: =IFERROR(__xludf.DUMMYFUNCTION("INDEX( SORT( FILTER({IPL_2020_to_2025_Raw!B:B, IPL_2020_to_2025_Raw!D:D,IPL_2020_to_2025_Raw!Q:Q}, IPL_2020_to_2025_Raw!A:A=A3), 3,FALSE), B3,2)"),"DC") -> DC | E3: =IFERROR(__xludf.DUMMYFUNCTION("INDEX( SORT( FILTER(IPL_2020_to_2025_Raw!Q:Q, IPL_2020_to_2025_Raw!A:A=A3), 1,FALSE), B3)"),30.0) -> 30 | F3: {=XLOOKUP(E3,IPL_2020_to_2025_Raw!Q:Q,IPL_2020_to_2025_Raw!R:R)} -> 64 | G3: {=XLOOKUP(E3,IPL_2020_to_2025_Raw!Q:Q,IPL_2020_to_2025_Raw!S:S)} -> 8.34 | H3: {=XLOOKUP(E3,IPL_2020_to_2025_Raw!Q:Q,IPL_2020_to_2025_Raw!V:V)} -> 4/24
A4: 2020 | B4: 2 | C4: =IFERROR(__xludf.DUMMYFUNCTION("INDEX( SORT( FILTER({IPL_2020_to_2025_Raw!B:B, IPL_2020_to_2025_Raw!C:C,IPL_2020_to_2025_Raw!Q:Q}, IPL_2020_to_2025_Raw!A:A=A4), 3,FALSE), B4,1)"),"Jasprit Bumrah") -> Jasprit Bumrah | D4: =IFERROR(__xludf.DUMMYFUNCTION("INDEX( SORT( FILTER({IPL_2020_to_2025_Raw!B:B, IPL_2020_to_2025_Raw!D:D,IPL_2020_to_2025_Raw!Q:Q}, IPL_2020_to_2025_Raw!A:A=A4), 3,FALSE), B4,2)"),"MI") -> MI | E4: =IFERROR(__xludf.DUMMYFUNCTION("LARGE(FILTER(IPL_2020_to_2025_Raw!Q:Q, IPL_2020_to_2025_Raw!A:A=A4),B4)"),27.0) -> 27 | F4: {=XLOOKUP(E4,IPL_2020_to_2025_Raw!Q:Q,IPL_2020_to_2025_Raw!R:R)} -> 58.1 | G4: {=XLOOKUP(E4,IPL_2020_to_2025_Raw!Q:Q,IPL_2020_to_2025_Raw!S:S)} -> 6.73 | H4: {=XLOOKUP(E4,IPL_2020_to_2025_Raw!Q:Q,IPL_2020_to_2025_Raw!V:V)} -> 4/14
A5: 2020 | B5: 3 | C5: =IFERROR(__xludf.DUMMYFUNCTION("INDEX( SORT( FILTER({IPL_2020_to_2025_Raw!B:B, IPL_2020_to_2025_Raw!C:C,IPL_2020_to_2025_Raw!Q:Q}, IPL_2020_to_2025_Raw!A:A=A5), 3,FALSE), B5,1)"),"Trent Boult") -> Trent Boult | D5: =IFERROR(__xludf.DUMMYFUNCTION("INDEX( SORT( FILTER({IPL_2020_to_2025_Raw!B:B, IPL_2020_to_2025_Raw!D:D,IPL_2020_to_2025_Raw!Q:Q}, IPL_2020_to_2025_Raw!A:A=A5), 3,FALSE), B5,2)"),"MI") -> MI | E5: =IFERROR(__xludf.DUMMYFUNCTION("LARGE(FILTER(IPL_2020_to_2025_Raw!Q:Q, IPL_2020_to_2025_Raw!A:A=A5),B5)"),25.0) -> 25 | F5: {=XLOOKUP(E5,IPL_2020_to_2025_Raw!Q:Q,IPL_2020_to_2025_Raw!R:R)} -> 57.3 | G5: {=XLOOKUP(E5,IPL_2020_to_2025_Raw!Q:Q,IPL_2020_to_2025_Raw!S:S)} -> 7.97 | H5: {=XLOOKUP(E5,IPL_2020_to_2025_Raw!Q:Q,IPL_2020_to_2025_Raw!V:V)} -> 3/21
A6: 2020 | B6: 4 | C6: =IFERROR(__xludf.DUMMYFUNCTION("INDEX( SORT( FILTER({IPL_2020_to_2025_Raw!B:B, IPL_2020_to_2025_Raw!C:C,IPL_2020_to_2025_Raw!Q:Q}, IPL_2020_to_2025_Raw!A:A=A6), 3,FALSE), B6,1)"),"Anrich Nortje") -> Anrich Nortje | D6: =IFERROR(__xludf.DUMMYFUNCTION("INDEX( SORT( FILTER({IPL_2020_to_2025_Raw!B:B, IPL_2020_to_2025_Raw!D:D,IPL_2020_to_2025_Raw!Q:Q}, IPL_2020_to_2025_Raw!A:A=A6), 3,FALSE), B6,2)"),"DC") -> DC | E6: =IFERROR(__xludf.DUMMYFUNCTION("LARGE(FILTER(IPL_2020_to_2025_Raw!Q:Q, IPL_2020_to_2025_Raw!A:A=A6),B6)"),22.0) -> 22 | F6: {=XLOOKUP(E6,IPL_2020_to_2025_Raw!Q:Q,IPL_2020_to_2025_Raw!R:R)} -> 58 | G6: {=XLOOKUP(E6,IPL_2020_to_2025_Raw!Q:Q,IPL_2020_to_2025_Raw!S:S)} -> 8.37 | H6: {=XLOOKUP(E6,IPL_2020_to_2025_Raw!Q:Q,IPL_2020_to_2025_Raw!V:V)} -> 3/21
A7: 2020 | B7: 5 | C7: =IFERROR(__xludf.DUMMYFUNCTION("INDEX( SORT( FILTER({IPL_2020_to_2025_Raw!B:B, IPL_2020_to_2025_Raw!C:C,IPL_2020_to_2025_Raw!Q:Q}, IPL_2020_to_2025_Raw!A:A=A7), 3,FALSE), B7,1)"),"Yuzvendra Chahal") -> Yuzvendra Chahal | D7: =IFERROR(__xludf.DUMMYFUNCTION("INDEX( SORT( FILTER({IPL_2020_to_2025_Raw!B:B, IPL_2020_to_2025_Raw!D:D,IPL_2020_to_2025_Raw!Q:Q}, IPL_2020_to_2025_Raw!A:A=A7), 3,FALSE), B7,2)"),"RCB") -> RCB | E7: =IFERROR(__xludf.DUMMYFUNCTION("LARGE(FILTER(IPL_2020_to_2025_Raw!Q:Q, IPL_2020_to_2025_Raw!A:A=A7),B7)"),21.0) -> 21 | F7: {=XLOOKUP(E7,IPL_2020_to_2025_Raw!Q:Q,IPL_2020_to_2025_Raw!R:R)} -> 58 | G7: {=XLOOKUP(E7,IPL_2020_to_2025_Raw!Q:Q,IPL_2020_to_2025_Raw!S:S)} -> 8.02 | H7: {=XLOOKUP(E7,IPL_2020_to_2025_Raw!Q:Q,IPL_2020_to_2025_Raw!V:V)} -> 3/18
A8: 2021 | B8: 1 | C8: =IFERROR(__xludf.DUMMYFUNCTION("INDEX( SORT( FILTER({IPL_2020_to_2025_Raw!B:B, IPL_2020_to_2025_Raw!C:C,IPL_2020_to_2025_Raw!Q:Q}, IPL_2020_to_2025_Raw!A:A=A8), 3,FALSE), B8,1)"),"Harshal Patel") -> Harshal Patel | D8: =IFERROR(__xludf.DUMMYFUNCTION("INDEX( SORT( FILTER({IPL_2020_to_2025_Raw!B:B, IPL_2020_to_2025_Raw!D:D,IPL_2020_to_2025_Raw!Q:Q}, IPL_2020_to_2025_Raw!A:A=A8), 3,FALSE), B8,2)"),"RCB") -> RCB | E8: =IFERROR(__xludf.DUMMYFUNCTION("LARGE(FILTER(IPL_2020_to_2025_Raw!Q:Q, IPL_2020_to_2025_Raw!A:A=A8),B8)"),32.0) -> 32 | F8: {=XLOOKUP(E8,IPL_2020_to_2025_Raw!Q:Q,IPL_2020_to_2025_Raw!R:R)} -> 57 | G8: {=XLOOKUP(E8,IPL_2020_to_2025_Raw!Q:Q,IPL_2020_to_2025_Raw!S:S)} -> 8.14 | H8: {=XLOOKUP(E8,IPL_2020_to_2025_Raw!Q:Q,IPL_2020_to_2025_Raw!V:V)} -> 5/27
A9: 2021 | B9: 2 | C9: =IFERROR(__xludf.DUMMYFUNCTION("INDEX( SORT( FILTER({IPL_2020_to_2025_Raw!B:B, IPL_2020_to_2025_Raw!C:C,IPL_2020_to_2025_Raw!Q:Q}, IPL_2020_to_2025_Raw!A:A=A9), 3,FALSE), B9,1)"),"Avesh Khan") -> Avesh Khan | D9: =IFERROR(__xludf.DUMMYFUNCTION("INDEX( SORT( FILTER({IPL_2020_to_2025_Raw!B:B, IPL_2020_to_2025_Raw!D:D,IPL_2020_to_2025_Raw!Q:Q}, IPL_2020_to_2025_Raw!A:A=A9), 3,FALSE), B9,2)"),"DC") -> DC | E9: =IFERROR(__xludf.DUMMYFUNCTION("LARGE(FILTER(IPL_2020_to_2025_Raw!Q:Q, IPL_2020_to_2025_Raw!A:A=A9),B9)"),24.0) -> 24 | F9: {=XLOOKUP(E9,IPL_2020_to_2025_Raw!Q:Q,IPL_2020_to_2025_Raw!R:R)} -> 58 | G9: {=XLOOKUP(E9,IPL_2020_to_2025_Raw!Q:Q,IPL_2020_to_2025_Raw!S:S)} -> 7.37 | H9: {=XLOOKUP(E9,IPL_2020_to_2025_Raw!Q:Q,IPL_2020_to_2025_Raw!V:V)} -> 4/24
A10: 2021 | B10: 3 | C10: =IFERROR(__xludf.DUMMYFUNCTION("INDEX( SORT( FILTER({IPL_2020_to_2025_Raw!B:B, IPL_2020_to_2025_Raw!C:C,IPL_2020_to_2025_Raw!Q:Q}, IPL_2020_to_2025_Raw!A:A=A10), 3,FALSE), B10,1)"),"Jasprit Bumrah") -> Jasprit Bumrah | D10: =IFERROR(__xludf.DUMMYFUNCTION("INDEX( SORT( FILTER({IPL_2020_to_2025_Raw!B:B, IPL_2020_to_2025_Raw!D:D,IPL_2020_to_2025_Raw!Q:Q}, IPL_2020_to_2025_Raw!A:A=A10), 3,FALSE), B10,2)"),"MI") -> MI | E10: =IFERROR(__xludf.DUMMYFUNCTION("LARGE(FILTER(IPL_2020_to_2025_Raw!Q:Q, IPL_2020_to_2025_Raw!A:A=A10),B10)"),21.0) -> 21 | F10: {=XLOOKUP(E10,IPL_2020_to_2025_Raw!Q:Q,IPL_2020_to_2025_Raw!R:R)} -> 58 | G10: {=XLOOKUP(E10,IPL_2020_to_2025_Raw!Q:Q,IPL_2020_to_2025_Raw!S:S)} -> 8.02 | H10: {=XLOOKUP(E10,IPL_2020_to_2025_Raw!Q:Q,IPL_2020_to_2025_Raw!V:V)} -> 3/18
A11: 2021 | B11: 4 | C11: =IFERROR(__xludf.DUMMYFUNCTION("INDEX( SORT( FILTER({IPL_2020_to_2025_Raw!B:B, IPL_2020_to_2025_Raw!C:C,IPL_2020_to_2025_Raw!Q:Q}, IPL_2020_to_2025_Raw!A:A=A11), 3,FALSE), B11,1)"),"Shardul Thakur") -> Shardul Thakur | D11: =IFERROR(__xludf.DUMMYFUNCTION("INDEX( SORT( FILTER({IPL_2020_to_2025_Raw!B:B, IPL_2020_to_2025_Raw!D:D,IPL_2020_to_2025_Raw!Q:Q}, IPL_2020_to_2025_Raw!A:A=A11), 3,FALSE), B11,2)"),"CSK") -> CSK | E11: =IFERROR(__xludf.DUMMYFUNCTION("LARGE(FILTER(IPL_2020_to_2025_Raw!Q:Q, IPL_2020_to_2025_Raw!A:A=A11),B11)"),21.0) -> 21 | F11: {=XLOOKUP(E11,IPL_2020_to_2025_Raw!Q:Q,IPL_2020_to_2025_Raw!R:R)} -> 58 | G11: {=XLOOKUP(E11,IPL_2020_to_2025_Raw!Q:Q,IPL_2020_to_2025_Raw!S:S)} -> 8.02 | H11: {=XLOOKUP(E11,IPL_2020_to_2025_Raw!Q:Q,IPL_2020_to_2025_Raw!V:V)} -> 3/18
A12: 2021 | B12: 5 | C12: =IFERROR(__xludf.DUMMYFUNCTION("INDEX( SORT( FILTER({IPL_2020_to_2025_Raw!B:B, IPL_2020_to_2025_Raw!C:C,IPL_2020_to_2025_Raw!Q:Q}, IPL_2020_to_2025_Raw!A:A=A12), 3,FALSE), B12,1)"),"Sunil Narine") -> Sunil Narine | D12: =IFERROR(__xludf.DUMMYFUNCTION("INDEX( SORT( FILTER({IPL_2020_to_2025_Raw!B:B, IPL_2020_to_2025_Raw!D:D,IPL_2020_to_2025_Raw!Q:Q}, IPL_2020_to_2025_Raw!A:A=A12), 3,FALSE), B12,2)"),"KKR") -> KKR | E12: =IFERROR(__xludf.DUMMYFUNCTION("LARGE(FILTER(IPL_2020_to_2025_Raw!Q:Q, IPL_2020_to_2025_Raw!A:A=A12),B12)"),21.0) -> 21 | F12: {=XLOOKUP(E12,IPL_2020_to_2025_Raw!Q:Q,IPL_2020_to_2025_Raw!R:R)} -> 58 | G12: {=XLOOKUP(E12,IPL_2020_to_2025_Raw!Q:Q,IPL_2020_to_2025_Raw!S:S)} -> 8.02 | H12: {=XLOOKUP(E12,IPL_2020_to_2025_Raw!Q:Q,IPL_2020_to_2025_Raw!V:V)} -> 3/18
A13: 2022 | B13: 1 | C13: =IFERROR(__xludf.DUMMYFUNCTION("INDEX( SORT( FILTER({IPL_2020_to_2025_Raw!B:B, IPL_2020_to_2025_Raw!C:C,IPL_2020_to_2025_Raw!Q:Q}, IPL_2020_to_2025_Raw!A:A=A13), 3,FALSE), B13,1)"),"Yuzvendra Chahal") -> Yuzvendra Chahal | D13: =IFERROR(__xludf.DUMMYFUNCTION("INDEX( SORT( FILTER({IPL_2020_to_2025_Raw!B:B, IPL_2020_to_2025_Raw!D:D,IPL_2020_to_2025_Raw!Q:Q}, IPL_2020_to_2025_Raw!A:A=A13), 3,FALSE), B13,2)"),"RR") -> RR | E13: =IFERROR(__xludf.DUMMYFUNCTION("LARGE(FILTER(IPL_2020_to_2025_Raw!Q:Q, IPL_2020_to_2025_Raw!A:A=A13),B13)"),27.0) -> 27 | F13: {=XLOOKUP(E13,IPL_2020_to_2025_Raw!Q:Q,IPL_2020_to_2025_Raw!R:R)} -> 58.1 | G13: {=XLOOKUP(E13,IPL_2020_to_2025_Raw!Q:Q,IPL_2020_to_2025_Raw!S:S)} -> 6.73 | H13: {=XLOOKUP(E13,IPL_2020_to_2025_Raw!Q:Q,IPL_2020_to_2025_Raw!V:V)} -> 4/14
A14: 2022 | B14: 2 | C14: =IFERROR(__xludf.DUMMYFUNCTION("INDEX( SORT( FILTER({IPL_2020_to_2025_Raw!B:B, IPL_2020_to_2025_Raw!C:C,IPL_2020_to_2025_Raw!Q:Q}, IPL_2020_to_2025_Raw!A:A=A14), 3,FALSE), B14,1)"),"Wanindu Hasaranga") -> Wanindu Hasaranga | D14: =IFERROR(__xludf.DUMMYFUNCTION("INDEX( SORT( FILTER({IPL_2020_to_2025_Raw!B:B, IPL_2020_to_2025_Raw!D:D,IPL_2020_to_2025_Raw!Q:Q}, IPL_2020_to_2025_Raw!A:A=A14), 3,FALSE), B14,2)"),"RCB") -> RCB | E14: =IFERROR(__xludf.DUMMYFUNCTION("LARGE(FILTER(IPL_2020_to_2025_Raw!Q:Q, IPL_2020_to_2025_Raw!A:A=A14),B14)"),26.0) -> 26 | F14: {=XLOOKUP(E14,IPL_2020_to_2025_Raw!Q:Q,IPL_2020_to_2025_Raw!R:R)} -> 60 | G14: {=XLOOKUP(E14,IPL_2020_to_2025_Raw!Q:Q,IPL_2020_to_2025_Raw!S:S)} -> 7.54 | H14: {=XLOOKUP(E14,IPL_2020_to_2025_Raw!Q:Q,IPL_2020_to_2025_Raw!V:V)} -> 4/20
A15: 2022 | B15: 3 | C15: =IFERROR(__xludf.DUMMYFUNCTION("INDEX( SORT( FILTER({IPL_2020_to_2025_Raw!B:B, IPL_2020_to_2025_Raw!C:C,IPL_2020_to_2025_Raw!Q:Q}, IPL_2020_to_2025_Raw!A:A=A15), 3,FALSE), B15,1)"),"Kagiso Rabada") -> Kagiso Rabada | D15: =IFERROR(__xludf.DUMMYFUNCTION("INDEX( SORT( FILTER({IPL_2020_to_2025_Raw!B:B, IPL_2020_to_2025_Raw!D:D,IPL_2020_to_2025_Raw!Q:Q}, IPL_2020_to_2025_Raw!A:A=A15), 3,FALSE), B15,2)"),"PBKS") -> PBKS | E15: =IFERROR(__xludf.DUMMYFUNCTION("LARGE(FILTER(IPL_2020_to_2025_Raw!Q:Q, IPL_2020_to_2025_Raw!A:A=A15),B15)"),23.0) -> 23 | F15: {=XLOOKUP(E15,IPL_2020_to_2025_Raw!Q:Q,IPL_2020_to_2025_Raw!R:R)} -> 50 | G15: {=XLOOKUP(E15,IPL_2020_to_2025_Raw!Q:Q,IPL_2020_to_2025_Raw!S:S)} -> 9.33 | H15: {=XLOOKUP(E15,IPL_2020_to_2025_Raw!Q:Q,IPL_2020_to_2025_Raw!V:V)} -> 4/33
A16: 2022 | B16: 4 | C16: =IFERROR(__xludf.DUMMYFUNCTION("INDEX( SORT( FILTER({IPL_2020_to_2025_Raw!B:B, IPL_2020_to_2025_Raw!C:C,IPL_2020_to_2025_Raw!Q:Q}, IPL_2020_to_2025_Raw!A:A=A16), 3,FALSE), B16,1)"),"Umran Malik") -> Umran Malik | D16: =IFERROR(__xludf.DUMMYFUNCTION("INDEX( SORT( FILTER({IPL_2020_to_2025_Raw!B:B, IPL_2020_to_2025_Raw!D:D,IPL_2020_to_2025_Raw!Q:Q}, IPL_2020_to_2025_Raw!A:A=A16), 3,FALSE), B16,2)"),"SRH") -> SRH | E16: =IFERROR(__xludf.DUMMYFUNCTION("LARGE(FILTER(IPL_2020_to_2025_Raw!Q:Q, IPL_2020_to_2025_Raw!A:A=A16),B16)"),22.0) -> 22 | F16: {=XLOOKUP(E16,IPL_2020_to_2025_Raw!Q:Q,IPL_2020_to_2025_Raw!R:R)} -> 58 | G16: {=XLOOKUP(E16,IPL_2020_to_2025_Raw!Q:Q,IPL_2020_to_2025_Raw!S:S)} -> 8.37 | H16: {=XLOOKUP(E16,IPL_2020_to_2025_Raw!Q:Q,IPL_2020_to_2025_Raw!V:V)} -> 3/21
A17: 2022 | B17: 5 | C17: =IFERROR(__xludf.DUMMYFUNCTION("INDEX( SORT( FILTER({IPL_2020_to_2025_Raw!B:B, IPL_2020_to_2025_Raw!C:C,IPL_2020_to_2025_Raw!Q:Q}, IPL_2020_to_2025_Raw!A:A=A17), 3,FALSE), B17,1)"),"Kuldeep Yadav") -> Kuldeep Yadav | D17: =IFERROR(__xludf.DUMMYFUNCTION("INDEX( SORT( FILTER({IPL_2020_to_2025_Raw!B:B, IPL_2020_to_2025_Raw!D:D,IPL_2020_to_2025_Raw!Q:Q}, IPL_2020_to_2025_Raw!A:A=A17), 3,FALSE), B17,2)"),"DC") -> DC | E17: =IFERROR(__xludf.DUMMYFUNCTION("LARGE(FILTER(IPL_2020_to_2025_Raw!Q:Q, IPL_2020_to_2025_Raw!A:A=A17),B17)"),21.0) -> 21 | F17: {=XLOOKUP(E17,IPL_2020_to_2025_Raw!Q:Q,IPL_2020_to_2025_Raw!R:R)} -> 58 | G17: {=XLOOKUP(E17,IPL_2020_to_2025_Raw!Q:Q,IPL_2020_to_2025_Raw!S:S)} -> 8.02 | H17: {=XLOOKUP(E17,IPL_2020_to_2025_Raw!Q:Q,IPL_2020_to_2025_Raw!V:V)} -> 3/18
A18: 2023 | B18: 1 | C18: =IFERROR(__xludf.DUMMYFUNCTION("INDEX( SORT( FILTER({IPL_2020_to_2025_Raw!B:B, IPL_2020_to_2025_Raw!C:C,IPL_2020_to_2025_Raw!Q:Q}, IPL_2020_to_2025_Raw!A:A=A18), 3,FALSE), B18,1)"),"Mohammed Shami") -> Mohammed Shami | D18: =IFERROR(__xludf.DUMMYFUNCTION("INDEX( SORT( FILTER({IPL_2020_to_2025_Raw!B:B, IPL_2020_to_2025_Raw!D:D,IPL_2020_to_2025_Raw!Q:Q}, IPL_2020_to_2025_Raw!A:A=A18), 3,FALSE), B18,2)"),"GT") -> GT | E18: =IFERROR(__xludf.DUMMYFUNCTION("LARGE(FILTER(IPL_2020_to_2025_Raw!Q:Q, IPL_2020_to_2025_Raw!A:A=A18),B18)"),28.0) -> 28 | F18: {=XLOOKUP(E18,IPL_2020_to_2025_Raw!Q:Q,IPL_2020_to_2025_Raw!R:R)} -> 65 | G18: {=XLOOKUP(E18,IPL_2020_to_2025_Raw!Q:Q,IPL_2020_to_2025_Raw!S:S)} -> 8.03 | H18: {=XLOOKUP(E18,IPL_2020_to_2025_Raw!Q:Q,IPL_2020_to_2025_Raw!V:V)} -> 4/17
A19: 2023 | B19: 2 | C19: =IFERROR(__xludf.DUMMYFUNCTION("INDEX( SORT( FILTER({IPL_2020_to_2025_Raw!B:B, IPL_2020_to_2025_Raw!C:C,IPL_2020_to_2025_Raw!Q:Q}, IPL_2020_to_2025_Raw!A:A=A19), 3,FALSE), B19,1)"),"Rashid Khan") -> Rashid Khan | D19: =IFERROR(__xludf.DUMMYFUNCTION("INDEX( SORT( FILTER({IPL_2020_to_2025_Raw!B:B, IPL_2020_to_2025_Raw!D:D,IPL_2020_to_2025_Raw!Q:Q}, IPL_2020_to_2025_Raw!A:A=A19), 3,FALSE), B19,2)"),"GT") -> GT | E19: =IFERROR(__xludf.DUMMYFUNCTION("LARGE(FILTER(IPL_2020_to_2025_Raw!Q:Q, IPL_2020_to_2025_Raw!A:A=A19),B19)"),27.0) -> 27 | F19: {=XLOOKUP(E19,IPL_2020_to_2025_Raw!Q:Q,IPL_2020_to_2025_Raw!R:R)} -> 58.1 | G19: {=XLOOKUP(E19,IPL_2020_to_2025_Raw!Q:Q,IPL_2020_to_2025_Raw!S:S)} -> 6.73 | H19: {=XLOOKUP(E19,IPL_2020_to_2025_Raw!Q:Q,IPL_2020_to_2025_Raw!V:V)} -> 4/14
A20: 2023 | B20: 3 | C20: =IFERROR(__xludf.DUMMYFUNCTION("INDEX( SORT( FILTER({IPL_2020_to_2025_Raw!B:B, IPL_2020_to_2025_Raw!C:C,IPL_2020_to_2025_Raw!Q:Q}, IPL_2020_to_2025_Raw!A:A=A20), 3,FALSE), B20,1)"),"Mohit Sharma") -> Mohit Sharma | D20: =IFERROR(__xludf.DUMMYFUNCTION("INDEX( SORT( FILTER({IPL_2020_to_2025_Raw!B:B, IPL_2020_to_2025_Raw!D:D,IPL_2020_to_2025_Raw!Q:Q}, IPL_2020_to_2025_Raw!A:A=A20), 3,FALSE), B20,2)"),"GT") -> GT | E20: =IFERROR(__xludf.DUMMYFUNCTION("LARGE(FILTER(IPL_2020_to_2025_Raw!Q:Q, IPL_2020_to_2025_Raw!A:A=A20),B20)"),27.0) -> 27 | F20: {=XLOOKUP(E20,IPL_2020_to_2025_Raw!Q:Q,IPL_2020_to_2025_Raw!R:R)} -> 58.1 | G20: {=XLOOKUP(E20,IPL_2020_to_2025_Raw!Q:Q,IPL_2020_to_2025_Raw!S:S)} -> 6.73 | H20: {=XLOOKUP(E20,IPL_2020_to_2025_Raw!Q:Q,IPL_2020_to_2025_Raw!V:V)} -> 4/14
A21: 2023 | B21: 4 | C21: =IFERROR(__xludf.DUMMYFUNCTION("INDEX( SORT( FILTER({IPL_2020_to_2025_Raw!B:B, IPL_2020_to_2025_Raw!C:C,IPL_2020_to_2025_Raw!Q:Q}, IPL_2020_to_2025_Raw!A:A=A21), 3,FALSE), B21,1)"),"Piyush Chawla") -> Piyush Chawla | D21: =IFERROR(__xludf.DUMMYFUNCTION("INDEX( SORT( FILTER({IPL_2020_to_2025_Raw!B:B, IPL_2020_to_2025_Raw!D:D,IPL_2020_to_2025_Raw!Q:Q}, IPL_2020_to_2025_Raw!A:A=A21), 3,FALSE), B21,2)"),"MI") -> MI | E21: =IFERROR(__xludf.DUMMYFUNCTION("LARGE(FILTER(IPL_2020_to_2025_Raw!Q:Q, IPL_2020_to_2025_Raw!A:A=A21),B21)"),22.0) -> 22 | F21: {=XLOOKUP(E21,IPL_2020_to_2025_Raw!Q:Q,IPL_2020_to_2025_Raw!R:R)} -> 58 | G21: {=XLOOKUP(E21,IPL_2020_to_2025_Raw!Q:Q,IPL_2020_to_2025_Raw!S:S)} -> 8.37 | H21: {=XLOOKUP(E21,IPL_2020_to_2025_Raw!Q:Q,IPL_2020_to_2025_Raw!V:V)} -> 3/21
A22: 2023 | B22: 5 | C22: =IFERROR(__xludf.DUMMYFUNCTION("INDEX( SORT( FILTER({IPL_2020_to_2025_Raw!B:B, IPL_2020_to_2025_Raw!C:C,IPL_2020_to_2025_Raw!Q:Q}, IPL_2020_to_2025_Raw!A:A=A22), 3,FALSE), B22,1)"),"Yuzvendra Chahal") -> Yuzvendra Chahal | D22: =IFERROR(__xludf.DUMMYFUNCTION("INDEX( SORT( FILTER({IPL_2020_to_2025_Raw!B:B, IPL_2020_to_2025_Raw!D:D,IPL_2020_to_2025_Raw!Q:Q}, IPL_2020_to_2025_Raw!A:A=A22), 3,FALSE), B22,2)"),"RR") -> RR | E22: =IFERROR(__xludf.DUMMYFUNCTION("LARGE(FILTER(IPL_2020_to_2025_Raw!Q:Q, IPL_2020_to_2025_Raw!A:A=A22),B22)"),21.0) -> 21 | F22: {=XLOOKUP(E22,IPL_2020_to_2025_Raw!Q:Q,IPL_2020_to_2025_Raw!R:R)} -> 58 | G22: {=XLOOKUP(E22,IPL_2020_to_2025_Raw!Q:Q,IPL_2020_to_2025_Raw!S:S)} -> 8.02 | H22: {=XLOOKUP(E22,IPL_2020_to_2025_Raw!Q:Q,IPL_2020_to_2025_Raw!V:V)} -> 3/18
A23: 2024 | B23: 1 | C23: =IFERROR(__xludf.DUMMYFUNCTION("INDEX( SORT( FILTER({IPL_2020_to_2025_Raw!B:B, IPL_2020_to_2025_Raw!C:C,IPL_2020_to_2025_Raw!Q:Q}, IPL_2020_to_2025_Raw!A:A=A23), 3,FALSE), B23,1)"),"Harshal Patel") -> Harshal Patel | D23: =IFERROR(__xludf.DUMMYFUNCTION("INDEX( SORT( FILTER({IPL_2020_to_2025_Raw!B:B, IPL_2020_to_2025_Raw!D:D,IPL_2020_to_2025_Raw!Q:Q}, IPL_2020_to_2025_Raw!A:A=A23), 3,FALSE), B23,2)"),"PBKS") -> PBKS | E23: =IFERROR(__xludf.DUMMYFUNCTION("LARGE(FILTER(IPL_2020_to_2025_Raw!Q:Q, IPL_2020_to_2025_Raw!A:A=A23),B23)"),24.0) -> 24 | F23: {=XLOOKUP(E23,IPL_2020_to_2025_Raw!Q:Q,IPL_2020_to_2025_Raw!R:R)} -> 58 | G23: {=XLOOKUP(E23,IPL_2020_to_2025_Raw!Q:Q,IPL_2020_to_2025_Raw!S:S)} -> 7.37 | H23: {=XLOOKUP(E23,IPL_2020_to_2025_Raw!Q:Q,IPL_2020_to_2025_Raw!V:V)} -> 4/24
A24: 2024 | B24: 2 | C24: =IFERROR(__xludf.DUMMYFUNCTION("INDEX( SORT( FILTER({IPL_2020_to_2025_Raw!B:B, IPL_2020_to_2025_Raw!C:C,IPL_2020_to_2025_Raw!Q:Q}, IPL_2020_to_2025_Raw!A:A=A24), 3,FALSE), B24,1)"),"Varun Chakravarthy") -> Varun Chakravarthy | D24: =IFERROR(__xludf.DUMMYFUNCTION("INDEX( SORT( FILTER({IPL_2020_to_2025_Raw!B:B, IPL_2020_to_2025_Raw!D:D,IPL_2020_to_2025_Raw!Q:Q}, IPL_2020_to_2025_Raw!A:A=A24), 3,FALSE), B24,2)"),"KKR") -> KKR | E24: =IFERROR(__xludf.DUMMYFUNCTION("LARGE(FILTER(IPL_2020_to_2025_Raw!Q:Q, IPL_2020_to_2025_Raw!A:A=A24),B24)"),21.0) -> 21 | F24: {=XLOOKUP(E24,IPL_2020_to_2025_Raw!Q:Q,IPL_2020_to_2025_Raw!R:R)} -> 58 | G24: {=XLOOKUP(E24,IPL_2020_to_2025_Raw!Q:Q,IPL_2020_to_2025_Raw!S:S)} -> 8.02 | H24: {=XLOOKUP(E24,IPL_2020_to_2025_Raw!Q:Q,IPL_2020_to_2025_Raw!V:V)} -> 3/18
A25: 2024 | B25: 3 | C25: =IFERROR(__xludf.DUMMYFUNCTION("INDEX( SORT( FILTER({IPL_2020_to_2025_Raw!B:B, IPL_2020_to_2025_Raw!C:C,IPL_2020_to_2025_Raw!Q:Q}, IPL_2020_to_2025_Raw!A:A=A25), 3,FALSE), B25,1)"),"Andre Russell") -> Andre Russell | D25: =IFERROR(__xludf.DUMMYFUNCTION("INDEX( SORT( FILTER({IPL_2020_to_2025_Raw!B:B, IPL_2020_to_2025_Raw!D:D,IPL_2020_to_2025_Raw!Q:Q}, IPL_2020_to_2025_Raw!A:A=A25), 3,FALSE), B25,2)"),"KKR") -> KKR | E25: =IFERROR(__xludf.DUMMYFUNCTION("LARGE(FILTER(IPL_2020_to_2025_Raw!Q:Q, IPL_2020_to_2025_Raw!A:A=A25),B25)"),19.0) -> 19 | F25: {=XLOOKUP(E25,IPL_2020_to_2025_Raw!Q:Q,IPL_2020_to_2025_Raw!R:R)} -> 52 | G25: {=XLOOKUP(E25,IPL_2020_to_2025_Raw!Q:Q,IPL_2020_to_2025_Raw!S:S)} -> 8.12 | H25: {=XLOOKUP(E25,IPL_2020_to_2025_Raw!Q:Q,IPL_2020_to_2025_Raw!V:V)} -> 3/21
A26: 2024 | B26: 4 | C26: =IFERROR(__xludf.DUMMYFUNCTION("INDEX( SORT( FILTER({IPL_2020_to_2025_Raw!B:B, IPL_2020_to_2025_Raw!C:C,IPL_2020_to_2025_Raw!Q:Q}, IPL_2020_to_2025_Raw!A:A=A26), 3,FALSE), B26,1)"),"Kuldeep Yadav") -> Kuldeep Yadav | D26: =IFERROR(__xludf.DUMMYFUNCTION("INDEX( SORT( FILTER({IPL_2020_to_2025_Raw!B:B, IPL_2020_to_2025_Raw!D:D,IPL_2020_to_2025_Raw!Q:Q}, IPL_2020_to_2025_Raw!A:A=A26), 3,FALSE), B26,2)"),"DC") -> DC | E26: =IFERROR(__xludf.DUMMYFUNCTION("LARGE(FILTER(IPL_2020_to_2025_Raw!Q:Q, IPL_2020_to_2025_Raw!A:A=A26),B26)"),19.0) -> 19 | F26: {=XLOOKUP(E26,IPL_2020_to_2025_Raw!Q:Q,IPL_2020_to_2025_Raw!R:R)} -> 52 | G26: {=XLOOKUP(E26,IPL_2020_to_2025_Raw!Q:Q,IPL_2020_to_2025_Raw!S:S)} -> 8.12 | H26: {=XLOOKUP(E26,IPL_2020_to_2025_Raw!Q:Q,IPL_2020_to_2025_Raw!V:V)} -> 3/21
A27: 2024 | B27: 5 | C27: =IFERROR(__xludf.DUMMYFUNCTION("INDEX( SORT( FILTER({IPL_2020_to_2025_Raw!B:B, IPL_2020_to_2025_Raw!C:C,IPL_2020_to_2025_Raw!Q:Q}, IPL_2020_to_2025_Raw!A:A=A27), 3,FALSE), B27,1)"),"Sunil Narine") -> Sunil Narine | D27: =IFERROR(__xludf.DUMMYFUNCTION("INDEX( SORT( FILTER({IPL_2020_to_2025_Raw!B:B, IPL_2020_to_2025_Raw!D:D,IPL_2020_to_2025_Raw!Q:Q}, IPL_2020_to_2025_Raw!A:A=A27), 3,FALSE), B27,2)"),"KKR") -> KKR | E27: =IFERROR(__xludf.DUMMYFUNCTION("LARGE(FILTER(IPL_2020_to_2025_Raw!Q:Q, IPL_2020_to_2025_Raw!A:A=A27),B27)"),17.0) -> 17 | F27: {=XLOOKUP(E27,IPL_2020_to_2025_Raw!Q:Q,IPL_2020_to_2025_Raw!R:R)} -> 38 | G27: {=XLOOKUP(E27,IPL_2020_to_2025_Raw!Q:Q,IPL_2020_to_2025_Raw!S:S)} -> 9.12 | H27: {=XLOOKUP(E27,IPL_2020_to_2025_Raw!Q:Q,IPL_2020_to_2025_Raw!V:V)} -> 3/14
A28: 2025 | B28: 1 | C28: =IFERROR(__xludf.DUMMYFUNCTION("INDEX( SORT( FILTER({IPL_2020_to_2025_Raw!B:B, IPL_2020_to_2025_Raw!C:C,IPL_2020_to_2025_Raw!Q:Q}, IPL_2020_to_2025_Raw!A:A=A28), 3,FALSE), B28,1)"),"Prasidh Krishna") -> Prasidh Krishna | D28: =IFERROR(__xludf.DUMMYFUNCTION("INDEX( SORT( FILTER({IPL_2020_to_2025_Raw!B:B, IPL_2020_to_2025_Raw!D:D,IPL_2020_to_2025_Raw!Q:Q}, IPL_2020_to_2025_Raw!A:A=A28), 3,FALSE), B28,2)"),"GT") -> GT | E28: =IFERROR(__xludf.DUMMYFUNCTION("LARGE(FILTER(IPL_2020_to_2025_Raw!Q:Q, IPL_2020_to_2025_Raw!A:A=A28),B28)"),25.0) -> 25 | F28: {=XLOOKUP(E28,IPL_2020_to_2025_Raw!Q:Q,IPL_2020_to_2025_Raw!R:R)} -> 57.3 | G28: {=XLOOKUP(E28,IPL_2020_to_2025_Raw!Q:Q,IPL_2020_to_2025_Raw!S:S)} -> 7.97 | H28: {=XLOOKUP(E28,IPL_2020_to_2025_Raw!Q:Q,IPL_2020_to_2025_Raw!V:V)} -> 3/21
A29: 2025 | B29: 2 | C29: =IFERROR(__xludf.DUMMYFUNCTION("INDEX( SORT( FILTER({IPL_2020_to_2025_Raw!B:B, IPL_2020_to_2025_Raw!C:C,IPL_2020_to_2025_Raw!Q:Q}, IPL_2020_to_2025_Raw!A:A=A29), 3,FALSE), B29,1)"),"Noor Ahmad") -> Noor Ahmad | D29: =IFERROR(__xludf.DUMMYFUNCTION("INDEX( SORT( FILTER({IPL_2020_to_2025_Raw!B:B, IPL_2020_to_2025_Raw!D:D,IPL_2020_to_2025_Raw!Q:Q}, IPL_2020_to_2025_Raw!A:A=A29), 3,FALSE), B29,2)"),"CSK") -> CSK | E29: =IFERROR(__xludf.DUMMYFUNCTION("LARGE(FILTER(IPL_2020_to_2025_Raw!Q:Q, IPL_2020_to_2025_Raw!A:A=A29),B29)"),24.0) -> 24 | F29: {=XLOOKUP(E29,IPL_2020_to_2025_Raw!Q:Q,IPL_2020_to_2025_Raw!R:R)} -> 58 | G29: {=XLOOKUP(E29,IPL_2020_to_2025_Raw!Q:Q,IPL_2020_to_2025_Raw!S:S)} -> 7.37 | H29: {=XLOOKUP(E29,IPL_2020_to_2025_Raw!Q:Q,IPL_2020_to_2025_Raw!V:V)} -> 4/24
A30: 2025 | B30: 3 | C30: =IFERROR(__xludf.DUMMYFUNCTION("INDEX( SORT( FILTER({IPL_2020_to_2025_Raw!B:B, IPL_2020_to_2025_Raw!C:C,IPL_2020_to_2025_Raw!Q:Q}, IPL_2020_to_2025_Raw!A:A=A30), 3,FALSE), B30,1)"),"Josh Hazlewood") -> Josh Hazlewood | D30: =IFERROR(__xludf.DUMMYFUNCTION("INDEX( SORT( FILTER({IPL_2020_to_2025_Raw!B:B, IPL_2020_to_2025_Raw!D:D,IPL_2020_to_2025_Raw!Q:Q}, IPL_2020_to_2025_Raw!A:A=A30), 3,FALSE), B30,2)"),"RCB") -> RCB | E30: =IFERROR(__xludf.DUMMYFUNCTION("LARGE(FILTER(IPL_2020_to_2025_Raw!Q:Q, IPL_2020_to_2025_Raw!A:A=A30),B30)"),22.0) -> 22 | F30: {=XLOOKUP(E30,IPL_2020_to_2025_Raw!Q:Q,IPL_2020_to_2025_Raw!R:R)} -> 58 | G30: {=XLOOKUP(E30,IPL_2020_to_2025_Raw!Q:Q,IPL_2020_to_2025_Raw!S:S)} -> 8.37 | H30: {=XLOOKUP(E30,IPL_2020_to_2025_Raw!Q:Q,IPL_2020_to_2025_Raw!V:V)} -> 3/21
A31: 2025 | B31: 4 | C31: =IFERROR(__xludf.DUMMYFUNCTION("INDEX( SORT( FILTER({IPL_2020_to_2025_Raw!B:B, IPL_2020_to_2025_Raw!C:C,IPL_2020_to_2025_Raw!Q:Q}, IPL_2020_to_2025_Raw!A:A=A31), 3,FALSE), B31,1)"),"Kuldeep Yadav") -> Kuldeep Yadav | D31: =IFERROR(__xludf.DUMMYFUNCTION("INDEX( SORT( FILTER({IPL_2020_to_2025_Raw!B:B, IPL_2020_to_2025_Raw!D:D,IPL_2020_to_2025_Raw!Q:Q}, IPL_2020_to_2025_Raw!A:A=A31), 3,FALSE), B31,2)"),"DC") -> DC | E31: =IFERROR(__xludf.DUMMYFUNCTION("LARGE(FILTER(IPL_2020_to_2025_Raw!Q:Q, IPL_2020_to_2025_Raw!A:A=A31),B31)"),21.0) -> 21 | F31: {=XLOOKUP(E31,IPL_2020_to_2025_Raw!Q:Q,IPL_2020_to_2025_Raw!R:R)} -> 58 | G31: {=XLOOKUP(E31,IPL_2020_to_2025_Raw!Q:Q,IPL_2020_to_2025_Raw!S:S)} -> 8.02 | H31: {=XLOOKUP(E31,IPL_2020_to_2025_Raw!Q:Q,IPL_2020_to_2025_Raw!V:V)} -> 3/18
A32: 2025 | B32: 5 | C32: =IFERROR(__xludf.DUMMYFUNCTION("INDEX( SORT( FILTER({IPL_2020_to_2025_Raw!B:B, IPL_2020_to_2025_Raw!C:C,IPL_2020_to_2025_Raw!Q:Q}, IPL_2020_to_2025_Raw!A:A=A32), 3,FALSE), B32,1)"),"Trent Boult") -> Trent Boult | D32: =IFERROR(__xludf.DUMMYFUNCTION("INDEX( SORT( FILTER({IPL_2020_to_2025_Raw!B:B, IPL_2020_to_2025_Raw!D:D,IPL_2020_to_2025_Raw!Q:Q}, IPL_2020_to_2025_Raw!A:A=A32), 3,FALSE), B32,2)"),"RR") -> RR | E32: =IFERROR(__xludf.DUMMYFUNCTION("LARGE(FILTER(IPL_2020_to_2025_Raw!Q:Q, IPL_2020_to_2025_Raw!A:A=A32),B32)"),19.0) -> 19 | F32: {=XLOOKUP(E32,IPL_2020_to_2025_Raw!Q:Q,IPL_2020_to_2025_Raw!R:R)} -> 52 | G32: {=XLOOKUP(E32,IPL_2020_to_2025_Raw!Q:Q,IPL_2020_to_2025_Raw!S:S)} -> 8.12 | H32: {=XLOOKUP(E32,IPL_2020_to_2025_Raw!Q:Q,IPL_2020_to_2025_Raw!V:V)} -> 3/21
